Workbook

Sheet 车手
A1: 车号 | B1: 车手 | C1: 所属 | D1: DR | E1: 技能1 | F1: 技能2
A2: 1 | B2: 维斯塔潘 | C2: 红牛 | D2: 100.5 | E2: 老潘课堂：雨天R值+0.5
A3: 11 | B3: 佩雷兹 | C3: 红牛 | D3: 99.8 | E3: 保胎大师：Stint过损耗点后R值损耗减0.3
A4: 16 | B4: 勒克莱尔 | C4: 法拉利 | D4: 100.4 | E4: 勒一圈：排位赛R值+0.5，但Q3以及Q1、Q2危险时限定 | F4: 极限哥：三圈及以上在其他车手DRS区，或其他车手在自己DRS区时，R+0.5，但每圈增加Ra10判定会不会操作变形，Ra10成功时R在基础值上倒扣0.5，该状态20圈后提升至Ra20
A5: 55 | B5: 塞恩斯 | C5: 法拉利 | D5: 99.8 | E5: Smooth Operator：防守时R值+0.3，形成火车队时R值再+0.3 | F5: 拉力传承：失控救车骰，90%成功 | G5: 车手都是自私的：在对LEC处于劣势且LEC有直接威胁的情况下R+0.5
A6: 44 | B6: 汉密尔顿 | C6: 奔驰 | D6: 100.4 | E6: 刘一圈：排位赛R值+0.5，但Q3以及Q1、Q2危险时限定 | F6: 振金超车：超车时骰子控制R值增点，成功则R+0.5；超车成功时会把人撞出去，自己无损
A7: 63 | B7: 拉塞尔 | C7: 奔驰 | D7: 99.9 | E7: 团队精神：车队指令要求让车时80%骰让车 | F7: 振金超车：超车时骰子控制R值增点，成功则R+0.5；超车成功时会把人撞出去，自己无损
A8: 10 | B8: 加斯利 | C8: 小红牛 | D8: 100.1 | E8: 斗小牛士：R值+0.5
A9: 22 | B9: 角田裕毅 | C9: 小红牛 | D9: 99.75 | E9: 武士道！：R+1，但多一个骰子判断下个超车点是否失误
A10: 5 | B10: 维特尔 | C10: 马丁 | D10: 100.3 | E10: 全能老农：与车队、车深度磨合，R值+0.8
A11: 18 | B11: 斯特罗尔 | C11: 马丁 | D11: 99.6 | E11: 直感A：防守位和雨天R值+0.3
A12: 14 | B12: 阿隆索 | C12: Alpine | D12: 100.5 | E12: WIDELONSO：防守位R值+0.8，若防守连续成功10次则骰子确认车辆性能损耗
A13: 31 | B13: 奥康 | C13: Alpine | D13: 99.7 | E13: 狮子：防守位下，无论进攻位是否是队友R值+0.5,无视车队指令
A14: 77 | B14: 博塔斯 | C14: 阿罗 | D14: 100.2 | E14: 昏厥起步：起步时R值-0.5，骰娘概率10%，后期稳定性上升后削减至5 - 2 - 1% | F14: 好大哥：在车队指令或帮助周冠宇防守时下R+1
A15: 24 | B15: 周冠宇 | C15: 阿罗 | D15: 99.5 | E15: 昏厥起步：起步时R值-0.5，骰娘概率10%，后期稳定性上升后削减至5 - 2 - 1% | F15: WIDEZHOU：防守位R+0.5
A16: 4 | B16: 诺里斯 | C16: 迈凯轮 | D16: 100.1 | E16: 盲盒车：每站骰子决定R值变化，分为-0.5, -0.3, 0, +0.3, +0.5五个档，车所有指标过90即取消
A17: 3 | B17: 里卡多 | C17: 迈凯轮 | D17: 99.6 | E17: 盲盒车：每站骰子决定R值变化，分为-0.5, -0.3, 0, +0.3, +0.5五个档，车所有指标过90即取消
A18: 20 | B18: 马格努森 | C18: 哈斯 | D18: 100.1 | E18: 画龙高手：防守位R+0.8，但会多一骰确定是否二次变线（会罚） | F18: 排位神车：排位赛R值+0.8
A19: 47 | B19: 米克 | C19: 哈斯 | D19: 99.5 | E19: 我也是舒马赫：R+1，但多一个骰子判断下个超车点是否失误 | F19: 排位神车：排位赛R值+0.8
A20: 23 | B20: 阿尔本 | C20: 威队 | D20: 100.1 | E20: 保胎大师：Stint过损耗点后R值损耗减0.3
A21: 6 | B21: 拉提菲 | C21: 威队 | D21: 99.5 | E21: 总导演：每站一个骰子确定会不会整活，撞出去后再一个骰子确认是否干涉比赛进程
A22: 27 | B22: 霍肯伯格 | C22: 马丁 | D22: 100.1 | E22: 嗦球队：对马格努森特攻，R值+0.5
B23: 菲蒂帕尔迪 | C23: 哈斯 | D23: 99.5
B24: 德弗里斯 | C24: 小红牛 | D24: 99.5 | E24: （疑似）最强代打：R值+1
A25: 81 | B25: 皮亚斯特里 | C25: 迈/Alpine | D25: 99.85 | E25: 冰人继承人：不会发生斗车事故、在事故后面时永不受损 | F25: 抽象怪（在？？赛后开始）：在不是澳大利亚的赛道认一个在围场的主场车手（不能是自己）当干爹，此时父子二人R+0.5并免除事故及大失败
A26: 39 | B26: 施瓦茨曼 | C26: 安德雷蒂 | D26: 99.6 | E26: ?
A27: 8 | B27: 格罗斯让 | C27: 安德雷蒂 | D27: 100.1 | E27: 大旗：默认团队精神，队友落后三个名次及以上或退赛时，Rating补偿+0.5 | F27: 车斗术：具有振金能力
F28: 振金流程：10%骰增加R值 -> 10%骰前车未发觉，同时成立时振。振金率1%。
A29: 鸡狗车技排名（不是DR）
A30: 灯 | B30: 17 | C30: 上限50
A31: 立希 | B31: 66
A32: Soyo | B32: 72 | C32: 认真模式86
A33: 爱音 | B33: 24
A34: 猫猫 | B34: 无聊的事情
A35: 祥子 | B35: ？？？
A36: 喵梦 | B36: 68
A37: 初华 | B37: 47
A38: 海铃 | B38: 34 | C38: 但摩托车是83
A39: 睦 | B39: 74 | C39: 黑化模式84

Sheet 三大件更换次数
A1: 车号 | B1: 车手 | C1: 所属 | D1: ICE | E1: ERS | F1: 变速箱
A2: 1 | B2: 维斯塔潘 | C2: 红牛 | D2: 0 | E2: 0 | F2: 0
A3: 11 | B3: 佩雷兹 | C3: 红牛 | D3: 0 | E3: 0 | F3: 0
A4: 16 | B4: 勒克莱尔 | C4: 法拉利 | D4: 0 | E4: 0 | F4: 0
A5: 55 | B5: 塞恩斯 | C5: 法拉利 | D5: 0 | E5: 0 | F5: 0
A6: 44 | B6: 汉密尔顿 | C6: 奔驰 | D6: 1 | E6: 1 | F6: 1
A7: 63 | B7: 拉塞尔 | C7: 奔驰 | D7: 1 | E7: 1 | F7: 1
A8: 10 | B8: 加斯利 | C8: 小红牛 | D8: 0 | E8: 0 | F8: 0
A9: 22 | B9: 角田裕毅 | C9: 小红牛 | D9: 0 | E9: 0 | F9: 0
A10: 5 | B10: 维特尔 | C10: 马丁 | D10: 1 | E10: 1 | F10: 1
A11: 18 | B11: 斯特罗尔 | C11: 马丁 | D11: 1 | E11: 1 | F11: 1
A12: 14 | B12: 阿隆索 | C12: Alpine | D12: 0 | E12: 0 | F12: 0
A13: 31 | B13: 奥康 | C13: Alpine | D13: 0 | E13: 0 | F13: 0
... A16: 4 | B16: 诺里斯 | C16: 迈凯轮 | D16: 0 | E16: 0 | F16: 0
A17: 3 81 | B17: 里卡多/皮亚斯特里 | C17: 迈凯轮 | D17: 2 | E17: 2 | F17: 2
A18: 20 | B18: 马格努森 | C18: 哈斯 | D18: 0 | E18: 0 | F18: 0
A19: 47 | B19: 米克舒马赫 | C19: 哈斯 | D19: 0 | E19: 0 | F19: 0
A20: 23 | B20: 阿尔本 | C20: 威队 | D20: 0 | E20: 0 | F20: 0
A21: 6 | B21: 拉提菲 | C21: 威队 | D21: 0 | E21: 0 | F21: 0

Sheet 预算帽
A1: 花费 | B1: 车队 | C1: 每月开销 | D1: 总计开销 | E1: 盈余 | F1: 3月升级 | G1: 3月造车 | H1: 4月升级 | I1: 4月造车 | J1: 5月升级 | K1: 5月造车 | L1: 6月升级 | M1: 6月造车 | N1: 7月升级 | O1: 7月造车 | P1: 8月升级 | Q1: 8月造车 | R1: 9月升级 | S1: 9月造车 | T1: 10月升级 | U1: 10月造车 | V1: 11月升级 | W1: 11月造车
A2: 1 | B2: 马丁 | C2: 54 | D2: =SUM(F2:W2) -> 0 | E2: =145-D2-C2 -> 91 | F2: 0 | G2: 0
A3: 2 | B3: 红牛 | C3: 54 | D3: =SUM(F3:W3) -> 1.04 | E3: =145-D3-C3 -> 89.96 | F3: 0 | G3: 0.04 | H3: 1
A4: 3 | B4: 奔驰 | C4: 54 | D4: =SUM(F4:W4) -> 2.04 | E4: =145-D4-C4 -> 88.96 | F4: 2 | G4: 0.04
A5: 4 | B5: 法拉利 | C5: 54 | D5: =SUM(F5:W5) -> 1.12 | E5: =145-D5-C5 -> 89.88 | F5: 0 | G5: 0.12 | H5: 1
A6: 5 | B6: 阿罗 | C6: 54 | D6: =SUM(F6:W6) -> 2.8 | E6: =145-D6-C6 -> 88.2 | F6: 1.4 | G6: 0 | H6: 1 | I6: 0.4
A7: 6 | B7: 哈斯 | C7: 54 | D7: =SUM(F7:W7) -> 2.84 | E7: =145-D7-C7 -> 88.16 | F7: 1.4 | G7: 0.04 | H7: 1 | I7: 0.4
A8: 7 | B8: Alpine | C8: 54 | D8: =SUM(F8:W8) -> 3.5 | E8: =145-D8-C8 -> 87.5 | F8: 1.75 | G8: 0 | H8: 1.5 | I8: 0.25
A9: 8 | B9: 小红牛 | C9: 54 | D9: =SUM(F9:W9) -> 3.54 | E9: =145-D9-C9 -> 87.46 | F9: 1.75 | G9: 0.04 | H9: 1.5 | I9: 0.25
A10: 9 | B10: 威廉姆斯 | C10: 54 | D10: =SUM(F10:W10) -> 4.7 | E10: =145-D10-C10 -> 86.3 | F10: 2.35 | G10: 0 | H10: 2 | I10: 0.35
A11: 10 | B11: 迈凯轮 | C11: 54 | D11: =SUM(F11:W11) -> 5.5 | E11: =145-D11-C11 -> 85.5 | F11: 3.75 | G11: 0 | H11: 1.5 | I11: 0.25

Sheet 巴林
A1: 车队 | B1: 机械 | C1: 空动 | D1: 动力 | E1: PR | F1: 稳定性 | H1: 车手 | I1: DR | J1: PR | K1: RO | L1: deltaR | M1: R | O1: 备注
A2: 法拉利 | B2: 98 | C2: 97 | D2: 99 | E2: =$B2*$B15+$C2*$C15+$D2*$D15 -> 308.65 | F2: 95 | H2: 勒克莱尔 | I2: 101.59999 | J2: 308.65 | K2: =I2*J2/100 -> 313.58837 | L2: 0.8 | M2: =K2+L2 -> 314.38837 | N2: 1 | O2: 技能0.5+0.3=0.8
A3: 红牛 | B3: 95 | C3: 100 | D3: 99 | E3: =$B3*$B15+$C3*$C15+$D3*$D15 -> 308.5 | F3: 96 | H3: 维斯塔潘 | I3: 101.6 | J3: 308.5 | K3: =I3*J3/100 -> 313.436 | M3: =K3+L3 -> 313.436 | N3: 2
A4: 奔驰 | B4: 99 | C4: 94 | D4: 100 | E4: =$B4*$B15+$C4*$C15+$D4*$D15 -> 307.6 | F4: 97 | H4: 汉密尔顿 | I4: 101.5 | J4: 307.6 | K4: =I4*J4/100 -> 312.214 | L4: 0.5 | M4: =K4+L4 -> 312.714 | N4: 3 | O4: 技能0.5
A5: 小红牛 | B5: 94 | C5: 92 | D5: 99 | E5: =$B5*$B15+$C5*$C15+$D5*$D15 -> 299 | F5: 96 | H5: 塞恩斯 | I5: 100 | J5: 308.65 | K5: =I5*J5/100 -> 308.65 | M5: =K5+L5 -> 308.65 | N5: 4
A6: 马丁 | B6: 93 | C6: 90 | D6: 100 | E6: =$B6*$B15+$C6*$C15+$D6*$D15 -> 296.8 | F6: 97 | H6: 佩雷兹 | I6: 99 | J6: 308.5 | K6: =I6*J6/100 -> 305.415 | M6: =K6+L6 -> 305.415 | N6: 5
A7: Alpine | B7: 93 | C7: 92 | D7: 97 | E7: =B7*B15+C7*C15+D7*D15 -> 295.9 | F7: 97 | H7: 拉塞尔 | I7: 99 | J7: 307.6 | K7: =I7*J7/100 -> 304.524 | M7: =K7+L7 -> 304.524 | N7: 6
A8: 阿罗 | B8: 90 | C8: 90 | D8: 99 | E8: =$B8*$B15+$C8*$C15+$D8*$D15 -> 292.5 | F8: 95 | H8: 阿隆索 | I8: 101.6 | J8: 295.9 | K8: =I8*J8/100 -> 300.6344 | M8: =K8+L8 -> 300.6344 | N8: 7
A9: 迈凯轮 | B9: 91 | C9: 87 | D9: 100 | E9: =$B9*$B15+$C9*$C15+$D9*$D15 -> 291.45 | F9: 96 | H9: 加斯利 | I9: 100 | J9: 299 | K9: =I9*J9/100 -> 299 | M9: =K9+L9 -> 299 | N9: 8
A10: 哈斯 | B10: 88 | C10: 91 | D10: 99 | E10: =$B10*$B15+$C10*$C15+$D10*$D15 -> 291.35 | F10: 96 | H10: 霍肯伯格 | I10: 100 | J10: 296.8 | K10: =I10*J10/100 -> 296.8 | M10: =K10+L10 -> 296.8 | N10: 9
A11: 威队 | B11: 88 | C11: 86 | D11: 100 | E11: =$B11*$B15+$C11*$C15+$D11*$D15 -> 287.1 | F11: 95 | H11: 角田裕毅 | I11: 99 | J11: 299 | K11: =I11*J11/100 -> 296.01 | M11: =K11+L11 -> 296.01 | N11: 10
H12: 斯特罗尔 | I12: 99 | J12: 296.8 | K12: =I12*J12/100 -> 293.832 | M12: =K12+L12 -> 293.832 | N12: 11
H13: 奥康 | I13: 99 | J13: 295.9 | K13: =I13*J13/100 -> 292.941 | M13: =K13+L13 -> 292.941 | N13: 12
B14: C(M) | C14: C(A) | D14: C(P) | H14: 博塔斯 | I14: 100 | J14: 292.5 | K14: =I14*J14/100 -> 292.5 | M14: =K14+L14 -> 292.5 | N14: 13
A15: 巴林 | B15: 1.1 | C15: 1.05 | D15: 1 | H15: 马格努森 | I15: 100 | J15: 291.35 | K15: =I15*J15/100 -> 291.35 | L15: 0.8 | M15: =K15+L15 -> 292.15 | N15: 14 | O15: 技能0.8
H16: 诺里斯 | I16: 100 | J16: 291.45 | K16: =I16*J16/100 -> 291.45 | M16: =K16+L16 -> 291.45 | N16: 15
H17: 里卡多 | I17: 99 | J17: 291.45 | K17: =I17*J17/100 -> 288.5355 | M17: =K17+L17 -> 288.5355 | N17: 16
H18: 周冠宇 | I18: 98.5 | J18: 292.5 | K18: =I18*J18/100 -> 288.1125 | M18: =K18+L18 -> 288.1125 | N18: 17
H19: 阿尔本 | I19: 100 | J19: 287.1 | K19: =I19*J19/100 -> 287.1 | M19: =K19+L19 -> 287.1 | N19: 18
H20: 米克舒马赫 | I20: 98 | J20: 291.35 | K20: =I20*J20/100 -> 285.523 | L20: 0.8 | M20: =K20+L20 -> 286.323 | N20: 19 | O20: 技能0.8
H21: 拉提菲 | I21: 98.5 | J21: 287.1 | K21: =I21*J21/100 -> 282.7935 | M21: =K21+L21 -> 282.7935 | N21: 20
A27: 名次 | B27: 车手 | C27: RO | D27: 起步轮胎 | E27: deltaR（胎） | F27: deltaR（技能） | G27: R | J27: 排名 | K27: 车手 | L27: RO | M27: Stint1衰减后
A28: 20 | B28: 拉提菲 | C28: 282.7935 | D28: 软 | G28: =C28+E28+F28 -> 282.7935 | J28: 1 | K28: 勒克莱尔 | L28: 312.9711 | M28: =L28*0.88 -> 275.41457
A29: 19 | B29: 米克舒马赫 | C29: 285.523 | D29: 软 | G29: =C29+E29+F29 -> 285.523 | J29: 2 | K29: 维斯塔潘 | L29: 313.436 | M29: =L29*0.88 -> 275.82368 | N29: =M29-M28 -> 0.409112
A30: 18 | B30: 阿尔本 | C30: 287.1 | D30: 软 | G30: =C30+E30+F30 -> 287.1 | J30: 3 | K30: 塞恩斯 | L30: 305.5635 | M30: =L30*0.88 -> 268.89588 | N30: =M30-M29 -> -6.9278
A31: 17 | B31: 周冠宇 | C31: 288.1125 | D31: 软 | G31: =C31+E31+F31 -> 288.1125 | J31: 4 | K31: 佩雷兹 | L31: 305.415 | M31: =L31*0.9 -> 274.8735 | N31: =M31-M30 -> 5.97762
A32: 16 | B32: 里卡多 | C32: 288.5355 | D32: 中 | E32: -0.5 | F32: 0.3 | G32: =C32+E32+F32 -> 288.3355 | J32: 5 | K32: 汉密尔顿 | L32: 312.214 | M32: =L32*0.88 -> 274.74832 | N32: =M32-M31 -> -0.12518
A33: 15 | B33: 诺里斯 | C33: 291.45 | D33: 中 | E33: -0.5 | F33: 0.5 | G33: =C33+E33+F33 -> 291.45 | J33: 6 | K33: 拉塞尔 | L33: 304.524 | M33: =L33*0.88 -> 267.98112 | N33: =M33-M32 -> -6.7672
A34: 14 | B34: 马格努森 | C34: 291.35 | D34: 软 | G34: =C34+E34+F34 -> 291.35 | J34: 7 | K34: 阿隆索 | L34: 300.6344 | M34: =L34*0.88 -> 264.55827 | N34: =M34-M33 -> -3.422848
A35: 13 | B35: 博塔斯 | C35: 292.5 | D35: 软 | G35: =C35+E35+F35 -> 292.5 | J35: 8 | K35: 加斯利 | L35: 299 | M35: =L35*0.88 -> 263.12 | N35: =M35-M34 -> -1.438272
A36: 12 | B36: 奥康 | C36: 292.941 | D36: 软 | G36: =C36+E36+F36 -> 292.941 | J36: 9 | K36: 霍肯伯格 | L36: 296.8 | M36: =L36*0.88 -> 261.184 | N36: =M36-M35 -> -1.936
A37: 11 | B37: 斯特罗尔 | C37: 293.832 | D37: 软 | G37: =C37+E37+F37 -> 293.832 | J37: 10 | K37: 角田裕毅 | L37: 296.01 | M37: =L37*0.88 -> 260.4888 | N37: =M37-M36 -> -0.6952
A38: 10 | B38: 角田裕毅 | C38: 296.01 | D38: 软 | G38: =C38+E38+F38 -> 296.01 | J38: 11 | K38: 斯特罗尔 | L38: 293.832 | M38: =L38*0.88 -> 258.57216 | N38: =M38-M37 -> -1.91664
A39: 9 | B39: 霍肯伯格 | C39: 296.8 | D39: 软 | G39: =C39+E39+F39 -> 296.8 | J39: 12 | K39: 奥康 | L39: 292.941 | M39: =L39*0.88 -> 257.78808 | N39: =M39-M38 -> -0.78408
A40: 8 | B40: 加斯利 | C40: 299 | D40: 软 | G40: =C40+E40+F40 -> 299 | J40: 13 | K40: 诺里斯 | L40: 291.45 | M40: =L40*0.9 -> 262.305 | N40: =M40-M39 -> 4.51692
A41: 7 | B41: 阿隆索 | C41: 300.6344 | D41: 软 | G41: =C41+E41+F41 -> 300.6344 | J41: 14 | K41: 马格努森 | L41: 291.35 | M41: =L41*0.88 -> 256.388 | N41: =M41-M40 -> -5.917
A42: 6 | B42: 拉塞尔 | C42: 304.524 | D42: 软 | G42: =C42+E42+F42 -> 304.524 | J42: 15 | K42: 里卡多 | L42: 288.3355 | M42: =L42*0.9 -> 259.50195 | N42: =M42-M41 -> 3.11395
A43: 5 | B43: 佩雷兹 | C43: 305.415 | D43: 软 | G43: =C43+E43+F43 -> 305.415 | J43: 16 | K43: 周冠宇 | L43: 288.1125 | M43: =L43*0.88 -> 253.539 | N43: =M43-M42 -> -5.96295
A44: 4 | B44: 塞恩斯 | C44: 305.5635 | D44: 软 | G44: =C44+E44+F44 -> 305.5635 | J44: 17 | K44: 博塔斯 | L44: 292.5 | M44: =L44*0.88 -> 257.4 | N44: =M44-M43 -> 3.861
A45: 3 | B45: 汉密尔顿 | C45: 312.214 | D45: 软 | G45: =C45+E45+F45 -> 312.214 | J45: 18 | K45: 阿尔本 | L45: 287.1 | M45: =L45*0.9 -> 258.39 | N45: =M45-M44 -> 0.99
...

Sheet 沙特
A1: 车队 | B1: 机械 | C1: 空动 | D1: 动力 | E1: PR | F1: 稳定性 | G1: 轮内稳定性 | H1: Rating | I1: 车手 | J1: DR | K1: PR | L1: RO | N1: 耐热 | O1: 车手 | P1: 耐热性 | Q1: 理由（参考23卡塔尔）
A2: 红牛 | B2: 95 | C2: 100 | D2: 99 | E2: =$B2*$B15+$C2*$C15+$D2*$D15 -> 311.9 | F2: 96 | G2: =RANDBETWEEN(1,100) -> 59 | H2: 1 | I2: 维斯塔潘 | J2: 100.5 | K2: 311.9 | L2: =J2*K2/100 -> 313.4595 | N2: 1 | O2: 维斯塔潘 | P2: 79 | Q2: 采访吐槽 d(70-85)
A3: 法拉利 | B3: 98 | C3: 97 | D3: 99 | E3: =$B3*$B15+$C3*$C15+$D3*$D15 -> 311.66 | F3: 95 | G3: =RANDBETWEEN(1,100) -> 69 | H3: 2 | I3: 勒克莱尔 | J3: 100.4 | K3: 311.66 | L3: =J3*K3/100 -> 312.90664 | N3: 2 | O3: 勒克莱尔 | P3: 79 | Q3: 采访吐槽 d(70-85)
A4: 奔驰 | B4: 99 | C4: 94 | D4: 100 | E4: =$B4*$B15+$C4*$C15+$D4*$D15 -> 310.52 | F4: 97 | G4: =RANDBETWEEN(1,100) -> 9 | H4: 3 | I4: 汉密尔顿 | J4: 100.4 | K4: 310.52 | L4: =J4*K4/100 -> 311.76208 | N4: 3 | O4: 汉密尔顿 | P4: 88 | Q4: d(70-98)
A5: 小红牛 | B5: 94 | C5: 92 | D5: 99 | E5: =$B5*$B15+$C5*$C15+$D5*$D15 -> 302.26 | F5: 96 | G5: =RANDBETWEEN(1,100) -> 92 | H5: 4 | I5: 佩雷兹 | J5: 99.8 | K5: 311.9 | L5: =J5*K5/100 -> 311.2762 | N5: 4 | O5: 佩雷兹 | P5: 84 | Q5: d(70-98)
A6: 马丁 | B6: 93 | C6: 90 | D6: 100 | E6: =$B6*$B15+$C6*$C15+$D6*$D15 -> 300.2 | F6: 97 | G6: =RANDBETWEEN(1,100) -> 69 | H6: 5 | I6: 塞恩斯 | J6: 99.8 | K6: 311.66 | L6: =J6*K6/100 -> 311.03668 | N6: 5 | O6: 塞恩斯 | P6: 84 | Q6: d(70-98)
A7: Alpine | B7: 93 | C7: 92 | D7: 97 | E7: =B7*B15+C7*C15+D7*D15 -> 299.06 | F7: 97 | G7: =RANDBETWEEN(1,100) -> 62 | H7: 6 | I7: 拉塞尔 | J7: 99.9 | K7: 310.52 | L7: =J7*K7/100 -> 310.20948 | N7: 6 | O7: 拉塞尔 | P7: 75（指定） | Q7: 差点热晕
A8: 阿罗 | B8: 90 | C8: 90 | D8: 99 | E8: =$B8*$B15+$C8*$C15+$D8*$D15 -> 296.1 | F8: 95 | G8: =RANDBETWEEN(1,100) -> 28 | H8: 7 | I8: 加斯利 | J8: 100.1 | K8: 302.26 | L8: =J8*K8/100 -> 302.56226 | N8: 7 | O8: 阿隆索 | P8: 99（指定） | Q8: 仙人掌一号
A9: 哈斯 | B9: 88 | C9: 91 | D9: 99 | E9: =$B9*$B15+$C9*$C15+$D9*$D15 -> 295.18 | F9: 96 | G9: =RANDBETWEEN(1,100) -> 30 | H9: 8 | I9: 角田裕毅 | J9: 99.75 | K9: 302.26 | L9: =J9*K9/100 -> 301.50435 | N9: 8 | O9: 加斯利 | P9: 87 | Q9: d(70-98)
A10: 迈凯轮 | B10: 91 | C10: 87 | D10: 100 | E10: =$B10*$B15+$C10*$C15+$D10*$D15 -> 294.96 | F10: 96 | G10: =RANDBETWEEN(1,100) -> 86 | H10: 9 | I10: 维特尔 | J10: 100.3 | K10: 300.2 | L10: =J10*K10/100 -> 301.1006 | N10: 9 | O10: 维特尔 | P10: 75（指定） | Q10: 病刚好（22巴林后）
A11: 威队 | B11: 88 | C11: 86 | D11: 100 | E11: =$B11*$B15+$C11*$C15+$D11*$D15 -> 290.88 | F11: 95 | G11: =RANDBETWEEN(1,100) -> 68 | H11: 10 | I11: 阿隆索 | J11: 100.5 | K11: 299.06 | L11: =J11*K11/100 -> 300.5553 | N11: 10 | O11: 角田裕毅 | P11: 70 | Q11: d(70-98)
H12: 11 | I12: 斯特罗尔 | J12: 99.6 | K12: 300.2 | L12: =J12*K12/100 -> 298.9992 | N12: 11 | O12: 斯特罗尔 | P12: 50（指定） | Q12: 已经抽过去了
H13: 12 | I13: 奥康 | J13: 99.7 | K13: 299.06 | L13: =J13*K13/100 -> 298.16282 | N13: 12 | O13: 博塔斯 | P13: 92 | Q13: d(70-98)
B14: C(M) | C14: C(A) | D14: C(P) | H14: 13 | I14: 博塔斯 | J14: 100.2 | K14: 296.1 | L14: =J14*K14/100 -> 296.6922 | N14: 13 | O14: 奥康 | P14: 65（指定） | Q14: 吐两次的含金量
A15: 沙特 | B15: 1 | C15: 1.08 | D15: 1.1 | F15: c | H15: 14 | I15: 马格努森 | J15: 100.1 | K15: 295.18 | L15: =J15*K15/100 -> 295.47518 | N15: 14 | O15: 马格努森 | P15: 90 | Q15: d(70-98)
H16: 15 | I16: 诺里斯 | J16: 100.1 | K16: 294.96 | L16: =J16*K16/100 -> 295.25496 | N16: 15 | O16: 诺里斯 | P16: 79 | Q16: 采访吐槽 d(70-85)
H17: 16 | I17: 周冠宇 | J17: 99.5 | K17: 296.1 | L17: =J17*K17/100 -> 294.6195 | N17: 16 | O17: 里卡多 | P17: 70 | Q17: d(70-98)
H18: 17 | I18: 里卡多 | J18: 99.6 | K18: 294.96 | L18: =J18*K18/100 -> 293.78016 | N18: 17 | O18: 周冠宇 | P18: 100（指定） | Q18: 仙人掌二号
H19: 18 | I19: 米克 | J19: 99.5 | K19: 295.18 | L19: =J19*K19/100 -> 293.7041 | N19: 18 | O19: 阿尔本 | P19: 70（指定） | Q19: 差点是抬出来的
H20: 19 | I20: 阿尔本 | J20: 100.1 | K20: 290.88 | L20: =J20*K20/100 -> 291.17088 | N20: 19 | O20: 米克 | P20: 92 | Q20: d(70-98)
H21: 20 | I21: 拉提菲 | J21: 99.5 | K21: 290.88 | L21: =J21*K21/100 -> 289.4256 | N21: 20 | O21: 拉提菲 | P21: 95 | Q21: d(70-98)
A26: Q | B26: 车号 | C26: 车手 | D26: DR | E26: PR | F26: RO | G26: deltaR | H26: R
A27: 1 | B27: 16 | C27: 勒克莱尔 | D27: 100.4 | E27: 311.66 | F27: =D27*E27/100 -> 312.90664 | G27: 1.3 | H27: =F27+G27 -> 314.20664 | I27: 0.8+0.5
A28: 2 | B28: 1 | C28: 维斯塔潘 | D28: 100.5 | E28: 311.9 | F28: =D28*E28/100 -> 313.4595 | G28: 0.6 | H28: =F28+G28 -> 314.0595
A29: 3 | B29: 44 | C29: 汉密尔顿 | D29: 100.4 | E29: 310.52 | F29: =D29*E29/100 -> 311.76208 | G29: 1.3 | H29: =F29+G29 -> 313.06208 | I29: 0.8+0.5
A30: 4 | B30: 55 | C30: 塞恩斯 | D30: 99.8 | E30: 311.66 | F30: =D30*E30/100 -> 311.03668 | G30: 0.8 | H30: =F30+G30 -> 311.83668
A31: 5 | B31: 11 | C31: 佩雷兹 | D31: 99.8 | E31: 311.9 | F31: =D31*E31/100 -> 311.2762 | G31: 0.4 | H31: =F31+G31 -> 311.6762
A32: 6 | B32: 63 | C32: 拉塞尔 | D32: 99.9 | E32: 310.52 | F32: =D32*E32/100 -> 310.20948 | H32: =F32+G32 -> 310.20948
A33: 7 | B33: 10 | C33: 加斯利 | D33: 100.1 | E33: 302.26 | F33: =D33*E33/100 -> 302.56226 | G33: 0.5 | H33: =F33+G33 -> 303.06226
A34: 8 | B34: 5 | C34: 维特尔 | D34: 100.3 | E34: 300.2 | F34: =D34*E34/100 -> 301.1006 | G34: 0.8 | H34: =F34+G34 -> 301.9006
A35: 9 | B35: 22 | C35: 角田裕毅 | D35: 99.75 | E35: 302.26 | F35: =D35*E35/100 -> 301.50435 | G35: 0.4 | H35: =F35+G35 -> 301.90435
A36: 10 | B36: 14 | C36: 阿隆索 | D36: 100.5 | E36: 299.06 | F36: =D36*E36/100 -> 300.5553 | H36: =F36+G36 -> 300.5553
A37: 11 | B37: 18 | C37: 斯特罗尔 | D37: 99.6 | E37: 300.2 | F37: =D37*E37/100 -> 298.9992 | H37: =F37+G37 -> 298.9992
A38: 12 | B38: 31 | C38: 奥康 | D38: 99.7 | E38: 299.06 | F38: =D38*E38/100 -> 298.16282 | H38: =F38+G38 -> 298.16282
A39: 13 | B39: 77 | C39: 博塔斯 | D39: 100.2 | E39: 296.1 | F39: =D39*E39/100 -> 296.6922 | H39: =F39+G39 -> 296.6922
A40: 14 | B40: 20 | C40: 马格努森 | D40: 100.1 | E40: 295.18 | F40: =D40*E40/100 -> 295.47518 | G40: 0.8 | H40: =F40+G40 -> 296.27518
A41: 15 | B41: 24 | C41: 周冠宇 | D41: 99.5 | E41: 296.1 | F41: =D41*E41/100 -> 294.6195 | G41: 0.8 | H41: =F41+G41 -> 295.4195
A42: 16 | B42: 4 | C42: 诺里斯 | D42: 100.1 | E42: 294.96 | F42: =D42*E42/100 -> 295.25496 | G42: -0.1 | H42: =F42+G42 -> 295.15496
A43: 17 | B43: 47 | C43: 米克 | D43: 99.5 | E43: 295.18 | F43: =D43*E43/100 -> 293.7041 | G43: 1.4 | H43: =F43+G43 -> 295.1041
A44: 18 | B44: 3 | C44: 里卡多 | D44: 99.6 | E44: 294.96 | F44: =D44*E44/100 -> 293.78016 | G44: 0.9 | H44: =F44+G44 -> 294.68016
...

Sheet 澳大利亚
A1: 车队 | B1: 机械 | C1: 空动 | D1: 动力 | E1: PR | F1: 稳定性
A2: 红牛 | B2: 95 | C2: 100 | D2: 99 | E2: =$B2*$B15+$C2*$C15+$D2*$D15 -> 303.95 | F2: 96
A3: 法拉利 | B3: 98 | C3: 97 | D3: 99.5 | E3: =$B3*$B15+$C3*$C15+$D3*$D15 -> 304.325 | F3: 95
A4: 奔驰 | B4: 99 | C4: 94 | D4: 101 | E4: =$B4*$B15+$C4*$C15+$D4*$D15 -> 303.75 | F4: 97
A5: 小红牛 | B5: 94 | C5: 92 | D5: 99 | E5: =$B5*$B15+$C5*$C15+$D5*$D15 -> 294.55 | F5: 96
A6: 马丁 | B6: 93 | C6: 90 | D6: 101 | E6: =$B6*$B15+$C6*$C15+$D6*$D15 -> 293.55 | F6: 97
A7: Alpine | B7: 93 | C7: 92 | D7: 97 | E7: =B7*B15+C7*C15+D7*D15 -> 291.45 | F7: 97.75
A8: 阿罗 | B8: 90 | C8: 90.75 | D8: 99.5 | E8: =$B8*$B15+$C8*$C15+$D8*$D15 -> 289.7625 | F8: 95
A9: 哈斯 | B9: 88 | C9: 91 | D9: 99.5 | E9: =$B9*$B15+$C9*$C15+$D9*$D15 -> 288.025 | F9: 96
A10: 迈凯轮 | B10: 91 | C10: 87 | D10: 101 | E10: =$B10*$B15+$C10*$C15+$D10*$D15 -> 288.4 | F10: 96.5
A11: 威队 | B11: 88.25 | C11: 86 | D11: 100 | E11: =$B11*$B15+$C11*$C15+$D11*$D15 -> 283.55 | F11: 95
B14: C(M) | C14: C(A) | D14: C(P)
A15: 澳大利亚 | B15: 1 | C15: 1.05 | D15: 1.05
A17: 车队 | B17: 升级内容骰点 | C17: 升级大项目 | D17: 升级小项骰 | E17: 升级小项 | F17: 升级点数骰 | G17: 升级点数 | H17: 附加PU升级？ | I17: PU升级点数
A18: 红牛 | B18: 3 | C18: PU | D18: 4 | E18: ERS | F18: 1 | G18: 0 | H18: X | I18: X
A19: 法拉利 | B19: 3 | C19: PU | D19: 1 | E19: ERS | F19: 4 | G19: 0.5 | H19: X | I19: X
A20: 奔驰 | B20: 3 | C20: PU | D20: 10 | E20: 爆Token | F20: X | G20: 1 | H20: X | I20: X
A21: 小红牛 | B21: 4 | C21: 稳定性 | D21: X | E21: X | F21: 1 | G21: 0 | H21: Y | I21: 0
A22: 马丁 | B22: 3 | C22: PU | D22: X | E22: X | F22: 7 | G22: X | H22: Ra70=39 -> Y | I22: 1
A23: Alpine | B23: 4 | C23: 稳定性 | D23: X | E23: X | F23: 9 | G23: 0.75 | H23: N | I23: X
A24: 阿罗 | B24: 2 | C24: 机械 | D24: 4 | E24: 底板补强 | F24: 8 | G24: 0.75 | H24: Y | I24: 0.5
A25: 哈斯 | B25: 2 | C25: 机械 | D25: 1 | E25: 底板补强 | F25: 1 | G25: 0 | H25: Y | I25: 0.5
A26: 迈凯轮 | B26: 4 | C26: 稳定性 | D26: X | E26: X | F26: 5 | G26: 0.5 | H26: Ra70=47 -> Y | I26: 1
A27: 威队 | B27: 1 | C27: 空气动力 | D27: 5 | E27: 底板 | F27: 3 | G27: 0.25 | H27: Ra30=77 -> N | I27: 0
A29: FP1
A30: 出车排序 | B30: 放车1D10 | C30: 队内顺序1D2 | D30: 飞行圈1D10 | E30: 队内顺序1D2 | F30: 调车骰1D5 | G30: PR修正系数 | H30: 轮胎选择1D2，1黄2白,白胎选手本场不还白，开两套红
A31: 红牛 | B31: 6 | C31: 2 | D31: 10 | E31: 2 | F31: 2 | G31: 0.4 | H31: 1
A32: 法拉利 | B32: 8 | C32: 2 | D32: 7 | E32: 2 | F32: 4 | G32: 0.8 | H32: 1
A33: 奔驰 | B33: 1 | C33: 1 | D33: 8 | E33: 2 | F33: 4 | G33: 0.8 | H33: 1
A34: 小红牛 | B34: 9 | C34: 1 | D34: 9 | E34: 1 | F34: 4 | G34: 0.8 | H34: 2
A35: 马丁 | B35: 5 | C35: 2 | D35: 6 | E35: 2 | F35: 4 | G35: 0.8 | H35: 1
A36: Alpine | B36: 10 | C36: 2 | D36: 3 | E36: 2 | F36: 4 | G36: 0.8 | H36: 1
A37: 阿罗 | B37: 3 | C37: 2 | D37: 4 | E37: 2 | F37: 5 | G37: 1 | H37: 2
A38: 哈斯 | B38: 2 | C38: 1 | D38: 1 | E38: 1 | F38: 1 | G38: 0.2 | H38: 2
A39: 迈凯伦 | B39: 4 | C39: 1 | D39: 2 | E39: 1 | F39: 5 | G39: 1 | H39: 1
A40: 威队 | B40: 7 | C40: 2 | D40: 5 | E40: 1 | F40: 2 | G40: 0.4 | H40: 1
A42: 车手 | B42: 练习赛放车顺序 | D42: 练习赛飞行圈顺序 | F42: 车手赛道适应骰1D5 | G42: DR修正系数 | H42: stint1模拟圈速（54圈油，4-12圈） | K42: 飞行圈1 | L42: 飞行圈2 | M42: stint2模拟圈速（30圈油，16-24圈）
A43: 维斯塔潘 | B43: 12 | D43: 20 | F43: 3 | G43: 0.15 | H43: 82.681492 | I43: 82.763268 | J43: 82.848341 | K43: 81.020212 | L43: 81.210636 | M43: 82.319304 | N43: 82.414325 | O43: 82.512675
A44: 佩雷兹 | B44: 11 | D44: 19 | F44: 5 | G44: 0.25 | H44: 82.908266 | I44: 82.962129 | J44: 83.018926 | K44: 81.252582 | L44: 81.406054 | M44: 82.457459 | N44: 82.523474 | O44: 82.592431
A45: 勒克莱尔 | B45: 16 | D45: 14 | F45: 3 | G45: 0.15 | H45: 82.615113 | I45: 82.697251 | J45: 82.782682 | K45: 80.956148 | L45: 81.14691 | M45: 82.254967 | N45: 82.350327 | O45: 82.449014
...

Sheet 伊莫拉
A1: 车队 | B1: 机械O | C1: 升级 | D1: 空动O | E1: 升级 | F1: 动力O | G1: 升级 | H1: PR | I1: 稳定性O | J1: 升级 | K1: 稳定性
A2: Alpine | B2: 93 | D2: 92 | E2: 1.5 | F2: 97 | H2: =($B$2+$C$2)*$B$15+($D$2+$E$2)*$C$15+($F$2+$G$2)*$D$15 -> 288.175 | I2: 97.75 | K2: =$I$2+$J$2 -> 97.75
A3: 奔驰 | B3: 99 | C3: 0.75 | D3: 94 | F3: 101 | H3: =($B$3+$C$3)*$B$15+($D$3+$E$3)*$C$15+($F$3+$G$3)*$D$15 -> 299.45 | I3: 97 | K3: =$I$3+$J$3 -> 97
A4: 阿罗 | B4: 90 | D4: 90.75 | E4: 1.5 | F4: 99.5 | H4: =($B$4+$C$4)*$B$15+($D$4+$E$4)*$C$15+($F$4+$G$4)*$D$15 -> 286.3625 | I4: 95 | K4: =$I$4+$J$4 -> 95
A5: 法拉利 | B5: 98 | C5: 0.75 | D5: 97 | F5: 99.5 | H5: =($B$5+$C$5)*$B$15+($D$5+$E$5)*$C$15+($F$5+$G$5)*$D$15 -> 300.1 | I5: 95 | K5: =$I$5+$J$5 -> 95
A6: 哈斯 | B6: 88 | D6: 91 | F6: 99.5 | H6: =($B$6+$C$6)*$B$15+($D$6+$E$6)*$C$15+($F$6+$G$6)*$D$15 -> 283.05 | I6: 96 | J6: 1.5 | K6: =$I$6+$J$6 -> 97.5
A7: 红牛 | B7: 95 | D7: 100 | E7: 0.75 | F7: 99 | H7: =($B$7+$C$7)*$B$15+($D$7+$E$7)*$C$15+($F$7+$G$7)*$D$15 -> 299.7875 | I7: 96 | K7: =$I$7+$J$7 -> 96
A8: 马丁 | B8: 93 | D8: 90 | F8: 101 | H8: =($B$8+$C$8)*$B$15+($D$8+$E$8)*$C$15+($F$8+$G$8)*$D$15 -> 288.5 | I8: 97 | J8: 1.5 | K8: =$I$8+$J$8 -> 98.5
A9: 迈凯轮 | B9: 91 | D9: 87 | E9: 1.5 | F9: 101 | H9: =($B$9+$C$9)*$B$15+($D$9+$E$9)*$C$15+($F$9+$G$9)*$D$15 -> 284.925 | I9: 96.5 | K9: =$I$9+$J$9 -> 96.5
A10: 威队 | B10: 88.25 | C10: 1.5 | D10: 86 | F10: 100 | H10: =($B$10+$C$10)*$B$15+($D$10+$E$10)*$C$15+($F$10+$G$10)*$D$15 -> 280.05 | I10: 95 | K10: =$I$10+$J$10 -> 95
A11: 小红牛 | B11: 94 | D11: 92 | E11: 1.5 | F11: 99 | H11: =($B$11+$C$11)*$B$15+($D$11+$E$11)*$C$15+($F$11+$G$11)*$D$15 -> 291.175 | I11: 96 | K11: =$I$11+$J$11 -> 96
B14: C(M) | C14: C(A) | D14: C(P)
A15: 伊莫拉 | B15: 1 | C15: 1.05 | D15: 1
A17: 车队 | B17: 升级内容骰点 | C17: 升级大项目 | D17: 升级小项骰 | E17: 升级小项 | F17: 升级点数骰 | G17: 升级点数 | H17: 倍率 | I17: 最终
A18: Alpine | B18: 1 | C18: 空动 | D18: 6 | E18: 尾翼 | F18: 9 | G18: 0.75 | H18: 2 | I18: =$G$18*$H18 -> 1.5
A19: 奔驰 | B19: 2 | C19: 机械 | D19: 1 | E19: 底板加固 | F19: 3 | G19: 0.25 | H19: 1 | I19: =$G$18*$H19 -> 0.75
A20: 阿罗 | B20: 1 | C20: 空动 | D20: 2 | E20: 前翼 | F20: 8 | G20: 0.75 | H20: 2 | I20: =$G$18*$H20 -> 1.5
A21: 法拉利 | B21: 2 | C21: 机械 | D21: 5 | E21: 减重 | F21: 8 | G21: 0.75 | H21: 1 | I21: =$G$18*$H21 -> 0.75
A22: 哈斯 | B22: 4 | C22: 稳定性 | D22: x | E22: x | F22: 9 | G22: 0.75 | H22: 2 | I22: =$G$18*$H22 -> 1.5
A23: 红牛 | B23: 1 | C23: 空动 | D23: 7 | E23: 前翼 | F23: 8 | G23: 0.75 | H23: 1 | I23: =$G$18*$H23 -> 0.75
A24: 马丁 | B24: 4 | C24: 稳定性 | D24: x | E24: x | F24: 3 | G24: 0.25 | H24: 2 | I24: =$G$24*$H24 -> 0.5
A25: 迈凯轮 | B25: 1 | C25: 空动 | D25: 8 | E25: 扩散器 | F25: 9 | G25: 0.75 | H25: 2 | I25: =$G$18*$H25 -> 1.5
A26: 威队 | B26: 2 | C26: 机械 | D26: 2 | E26: 减重 | F26: 3 | G26: 0.25 | H26: 2 | I26: =$G$18*$H26 -> 1.5
A27: 小红牛 | B27: 1 | C27: 空动 | D27: 7 | E27: 前翼 | F27: 10 | G27: 1 | H27: 2 | I27: =$G$18*$H27 -> 1.5
A29: 车手 | B29: 车队 | C29: DR | D29: PR | E29: RO
A30: 勒克莱尔 | B30: 法拉利 | C30: 100.4 | D30: =$H$5 -> 300.1 | E30: =C30*D30/100 -> 301.3004
A31: 维斯塔潘 | B31: 红牛 | C31: 100.5 | D31: =$H$7 -> 299.7875 | E31: =C31*D31/100 -> 301.28644
A32: 汉密尔顿 | B32: 奔驰 | C32: 100.4 | D32: =$H$3 -> 299.45 | E32: =C32*D32/100 -> 300.6478
A33: 塞恩斯 | B33: 法拉利 | C33: 99.9 | D33: =$H$5 -> 300.1 | E33: =C33*D33/100 -> 299.7999
A34: 佩雷兹 | B34: 红牛 | C34: 99.9 | D34: =$H$7 -> 299.7875 | E34: =C34*D34/100 -> 299.48771
A35: 拉塞尔 | B35: 奔驰 | C35: 99.95 | D35: =$H$3 -> 299.45 | E35: =C35*D35/100 -> 299.30027
A36: 加斯利 | B36: 小红牛 | C36: 100.1 | D36: =$H$11 -> 291.175 | E36: =C36*D36/100 -> 291.46618
A37: 角田裕毅 | B37: 小红牛 | C37: 99.8 | D37: =$H$11 -> 291.175 | E37: =C37*D37/100 -> 290.59265
A38: 阿隆索 | B38: Alpine | C38: 100.5 | D38: =$H$2 -> 288.175 | E38: =C38*D38/100 -> 289.61588
A39: 维特尔 | B39: 马丁 | C39: 100.3 | D39: =$H$8 -> 288.5 | E39: =C39*D39/100 -> 289.3655
A40: 奥康 | B40: Alpine | C40: 99.85 | D40: =$H$2 -> 288.175 | E40: =C40*D40/100 -> 287.74274
A41: 斯特罗尔 | B41: 马丁 | C41: 99.65 | D41: =$H$8 -> 288.5 | E41: =C41*D41/100 -> 287.49025
A42: 博塔斯 | B42: 阿罗 | C42: 100.2 | D42: =$H$4 -> 286.3625 | E42: =C42*D42/100 -> 286.93523
A43: 周冠宇 | B43: 阿罗 | C43: 99.6 | D43: =$H$4 -> 286.3625 | E43: =C43*D43/100 -> 285.21705
A44: 诺里斯 | B44: 迈凯轮 | C44: 100.1 | D44: =$H$9 -> 284.925 | E44: =C44*D44/100 -> 285.20992
...

Sheet 迈阿密
A1: 车队 | B1: 机械O | C1: 升级 | D1: 机械 | E1: 空动O | F1: 升级 | G1: 空动 | H1: 动力O | I1: 升级 | J1: 动力 | K1: PR | L1: 稳定性O | M1: 升级 | N1: 稳定性
A2: Alpine | B2: 93 | C2: =IF($B18=2,$I18,0) -> 0 | D2: =$B2+$C2 -> 93 | E2: 93.5 | F2: =IF($B18=1,$I18,0) -> 1 | G2: =$E2+$F2 -> 94.5 | H2: 97 | I2: =IF($B18=3,$I18,0) -> 0 | J2: =$H2+$I2 -> 97 | K2: =$D2*$B$15+$G2*$C$15+$J2*$D$15 -> 300.8875 | L2: 97.75 | M2: =IF($B18=4,$I18,0) -> 0 | N2: =$L2+$M2 -> 97.75
A3: 奔驰 | B3: 99.75 | C3: =IF($B19=2,$I19,0) -> 0 | D3: =$B3+$C3 -> 99.75 | E3: 94 | F3: =IF($B19=1,$I19,0) -> 0.9 | G3: =$E3+$F3 -> 94.9 | H3: 101 | I3: =IF($B19=3,$I19,0) -> 0 | J3: =$H3+$I3 -> 101 | K3: =$D3*$B$15+$G3*$C$15+$J3*$D$15 -> 312.7425 | L3: 97 | M3: =IF($B19=4,$I19,0) -> 0 | N3: =$L3+$M3 -> 97
A4: 阿罗 | B4: 90 | C4: =IF($B20=2,$I20,0) -> 0 | D4: =$B4+$C4 -> 90 | E4: 92.25 | F4: =IF($B20=1,$I20,0) -> 1 | G4: =$E4+$F4 -> 93.25 | H4: 99.4 | I4: =IF($B20=3,$I20,0) -> 0 | J4: =$H4+$I4 -> 99.4 | K4: =$D4*$B$15+$G4*$C$15+$J4*$D$15 -> 298.64375 | L4: 95 | M4: =IF($B20=4,$I20,0) -> 0 | N4: =$L4+$M4 -> 95
A5: 法拉利 | B5: 98.75 | C5: =IF($B21=2,$I21,0) -> 0 | D5: =$B5+$C5 -> 98.75 | E5: 97 | F5: =IF($B21=1,$I21,0) -> 0.25 | G5: =$E5+$F5 -> 97.25 | H5: 99.4 | I5: =IF($B21=3,$I21,0) -> 0 | J5: =$H5+$I5 -> 99.4 | K5: =$D5*$B$15+$G5*$C$15+$J5*$D$15 -> 312.56875 | L5: 95 | M5: =IF($B21=4,$I21,0) -> 0 | N5: =$L5+$M5 -> 95
A6: 哈斯 | B6: 88 | C6: =IF($B22=2,$I22,0) -> 0 | D6: =$B6+$C6 -> 88 | E6: 91 | F6: =IF($B22=1,$I22,0) -> 0 | G6: =$E6+$F6 -> 91 | H6: 99.4 | I6: =IF($B22=3,$I22,0) -> 0 | J6: =$H6+$I6 -> 99.4 | K6: =$D6*$B$15+$G6*$C$15+$J6*$D$15 -> 294.025 | L6: 97.5 | M6: =IF($B22=4,$I22,0) -> 0 | N6: =$L6+$M6 -> 97.5
A7: 红牛 | B7: 95 | C7: =IF($B23=2,$I23,0) -> 0 | D7: =$B7+$C7 -> 95 | E7: 100.75 | F7: =IF($B23=1,$I23,0) -> 0 | G7: =$E7+$F7 -> 100.75 | H7: 99 | I7: =IF($B23=3,$I23,0) -> 0.75 | J7: =$H7+$I7 -> 99.75 | K7: =$D7*$B$15+$G7*$C$15+$J7*$D$15 -> 312.55625 | L7: 96 | M7: =IF($B23=4,$I23,0) -> 0 | N7: =$L7+$M7 -> 96
A8: 马丁 | B8: 93 | C8: =IF($B24=2,$I24,0) -> 0 | D8: =$B8+$C8 -> 93 | E8: 90 | F8: =IF($B24=1,$I24,0) -> 0 | G8: =$E8+$F8 -> 90 | H8: 101 | I8: =IF($B24=3,$I24,0) -> 0 | J8: =$H8+$I8 -> 101 | K8: =$D8*$B$15+$G8*$C$15+$J8*$D$15 -> 300.05 | L8: 98.5 | M8: =IF($B24=4,$I24,0) -> 1 | N8: =$L8+$M8 -> 99.5
A9: 迈凯轮 | B9: 91 | C9: =IF($B25=2,$I25,0) -> 0 | D9: =$B9+$C9 -> 91 | E9: 88.5 | F9: =IF($B25=1,$I25,0) -> 1 | G9: =$E9+$F9 -> 89.5 | H9: 101 | I9: =IF($B25=3,$I25,0) -> 0 | J9: =$H9+$I9 -> 101 | K9: =$D9*$B$15+$G9*$C$15+$J9*$D$15 -> 297.3125 | L9: 96.5 | M9: =IF($B25=4,$I25,0) -> 0 | N9: =$L9+$M9 -> 96.5
A10: 威队 | B10: 89.75 | C10: =IF($B26=2,$I26,0) -> 0 | D10: =$B10+$C10 -> 89.75 | E10: 86 | F10: =IF($B26=1,$I26,0) -> 1 | G10: =$E10+$F10 -> 87 | H10: 100 | I10: =IF($B26=3,$I26,0) -> 0 | J10: =$H10+$I10 -> 100 | K10: =$D10*$B$15+$G10*$C$15+$J10*$D$15 -> 292.25 | L10: 95 | M10: =IF($B26=4,$I26,0) -> 0 | N10: =$L10+$M10 -> 95
A11: 小红牛 | B11: 94 | C11: =IF($B27=2,$I27,0) -> 0 | D11: =$B11+$C11 -> 94 | E11: 93.5 | F11: =IF($B27=1,$I27,0) -> 0 | G11: =$E11+$F11 -> 93.5 | H11: 99 | I11: 0.75 | J11: =$H11+$I11 -> 99.75 | K11: =$D11*$B$15+$G11*$C$15+$J11*$D$15 -> 303.6625 | L11: 96 | M11: =IF($B27=4,$I27,0) -> 1 | N11: =$L11+$M11 -> 97
A12: 安德雷蒂 | B12: 92 | C12: 0 | D12: =$B12+$C12 -> 92 | E12: 94 | F12: 0 | G12: =$E12+$F12 -> 94 | H12: 97 | I12: 0 | J12: =$H12+$I12 -> 97 | K12: =$D12*$B$15+$G12*$C$15+$J12*$D$15 -> 299.25 | L12: 97 | M12: 0 | N12: =$L12+$M12 -> 97
B14: C(M) | C14: C(A) | D14: C(P)
A15: 迈阿密 | B15: 1.1 | C15: 1.075 | D15: 1
A17: 车队 | B17: 升级内容骰点 | C17: 升级大项目 | D17: 升级小项骰 | E17: 升级小项 | F17: 升级点数骰 | G17: 升级点数 | H17: 倍率 | I17: 最终 | K17: 升级内容 | N17: 空力 | O17: 机械 | P17: PU | Q17: 稳定性
A18: Alpine | B18: 1 | C18: =LOOKUP($B18,$K$18:$K$21,$L$18:$L$21) -> 空力 | D18: 5 | E18: =INDEX($N$18:$Q$27,$D18,$B18) -> 底板 | F18: 7 | G18: =LOOKUP($F18,$R$18:$R$27,$S$18:$S$27) -> 0.5 | H18: 2 | I18: =$G18*$H18 -> 1 | K18: 1 | L18: 空力 | M18: 1 | N18: 尾翼 | O18: 底板加固 | P18: ERS | Q18: 稳定性 | R18: 1 | S18: 0
A19: 奔驰 | B19: 1 | C19: =LOOKUP($B19,$K$18:$K$21,$L$18:$L$21) -> 空力 | D19: 10 | E19: =INDEX($N$18:$Q$27,$D19,$B19) -> 底板 | F19: 10 | G19: =LOOKUP($F19,$R$18:$R$27,$S$18:$S$27) -> 1 | H19: 0.9 | I19: =$G19*$H19 -> 0.9 | J19: 埃利奥特开坑 | K19: 2 | L19: 机械 | M19: 2 | N19: 前翼 | O19: 减重 | P19: 冷却 | Q19: 稳定性 | R19: 2 | S19: 0.25
A20: 阿罗 | B20: 1 | C20: =LOOKUP($B20,$K$18:$K$21,$L$18:$L$21) -> 空力 | D20: 5 | E20: =INDEX($N$18:$Q$27,$D20,$B20) -> 底板 | F20: 6 | G20: =LOOKUP($F20,$R$18:$R$27,$S$18:$S$27) -> 0.5 | H20: 2 | I20: =$G20*$H20 -> 1 | K20: 3 | L20: PU | M20: 3 | N20: 扩散器 | O20: 悬挂 | P20: ICE | Q20: 稳定性 | R20: 3 | S20: 0.25
A21: 法拉利 | B21: 1 | C21: =LOOKUP($B21,$K$18:$K$21,$L$18:$L$21) -> 空力 | D21: 9 | E21: =INDEX($N$18:$Q$27,$D21,$B21) -> 侧箱 | F21: 2 | G21: =LOOKUP($F21,$R$18:$R$27,$S$18:$S$27) -> 0.25 | H21: 1 | I21: =$G21*$H21 -> 0.25 | K21: 4 | L21: 稳定性 | M21: 4 | N21: 侧箱 | O21: 底板加固 | P21: ERS | Q21: 稳定性 | R21: 4 | S21: 0.5
A22: 哈斯 | B22: 1 | C22: =LOOKUP($B22,$K$18:$K$21,$L$18:$L$21) -> 空力 | D22: 10 | E22: =INDEX($N$18:$Q$27,$D22,$B22) -> 底板 | F22: 1 | G22: =LOOKUP($F22,$R$18:$R$27,$S$18:$S$27) -> 0 | H22: 2 | I22: =$G22*$H22 -> 0 | M22: 5 | N22: 底板 | O22: 减重 | P22: 冷却 | Q22: 稳定性 | R22: 5 | S22: 0.5
A23: 红牛 | B23: 3 | C23: =LOOKUP($B23,$K$18:$K$21,$L$18:$L$21) -> PU | D23: 6 | E23: =INDEX($N$18:$Q$27,$D23,$B23) -> ICE | F23: 9 | G23: =LOOKUP($F23,$R$18:$R$27,$S$18:$S$27) -> 0.75 | H23: 1 | I23: =$G23*$H23 -> 0.75 | M23: 6 | N23: 尾翼 | O23: 悬挂 | P23: ICE | Q23: 稳定性 | R23: 6 | S23: 0.5
A24: 马丁 | B24: 4 | C24: =LOOKUP($B24,$K$18:$K$21,$L$18:$L$21) -> 稳定性 | D24: 5 | E24: =INDEX($N$18:$Q$27,$D24,$B24) -> 稳定性 | F24: 4 | G24: =LOOKUP($F24,$R$18:$R$27,$S$18:$S$27) -> 0.5 | H24: 2 | I24: =$G24*$H24 -> 1 | M24: 7 | N24: 前翼 | O24: 底板加固 | P24: ERS | Q24: 稳定性 | R24: 7 | S24: 0.5
A25: 迈凯轮 | B25: 1 | C25: =LOOKUP($B25,$K$18:$K$21,$L$18:$L$21) -> 空力 | D25: 6 | E25: =INDEX($N$18:$Q$27,$D25,$B25) -> 尾翼 | F25: 5 | G25: =LOOKUP($F25,$R$18:$R$27,$S$18:$S$27) -> 0.5 | H25: 2 | I25: =$G25*$H25 -> 1 | M25: 8 | N25: 扩散器 | O25: 减重 | P25: 冷却 | Q25: 稳定性 | R25: 8 | S25: 0.75
A26: 威队 | B26: 1 | C26: =LOOKUP($B26,$K$18:$K$21,$L$18:$L$21) -> 空力 | D26: 9 | E26: =INDEX($N$18:$Q$27,$D26,$B26) -> 侧箱 | F26: 5 | G26: =LOOKUP($F26,$R$18:$R$27,$S$18:$S$27) -> 0.5 | H26: 2 | I26: =$G26*$H26 -> 1 | M26: 9 | N26: 侧箱 | O26: 悬挂 | P26: ICE | Q26: 稳定性 | R26: 9 | S26: 0.75
A27: 小红牛 | B27: 4 | C27: =LOOKUP($B27,$K$18:$K$21,$L$18:$L$21) -> 稳定性 | D27: 9 | E27: =INDEX($N$18:$Q$27,$D27,$B27) -> 稳定性 | F27: 5 | G27: =LOOKUP($F27,$R$18:$R$27,$S$18:$S$27) -> 0.5 | H27: 2 | I27: =$G27*$H27 -> 1 | M27: 10 | N27: 底板 | O27: Reroll | P27: 起Token | Q27: 稳定性 | R27: 10 | S27: 1
A29: 车手 | B29: 车队 | C29: DR | D29: PR | E29: RO
A30: 维斯塔潘 | B30: 红牛 | C30: 100.5 | D30: =INDEX($A$2:$K$12,MATCH($B30,$A$2:$A$12,0),11) -> 312.55625 | E30: =C30*D30/100 -> 314.11903
A31: 汉密尔顿 | B31: 奔驰 | C31: 100.4 | D31: =INDEX($A$2:$K$12,MATCH($B31,$A$2:$A$12,0),11) -> 312.7425 | E31: =C31*D31/100 -> 313.99347
A32: 勒克莱尔 | B32: 法拉利 | C32: 100.4 | D32: =INDEX($A$2:$K$12,MATCH($B32,$A$2:$A$12,0),11) -> 312.56875 | E32: =C32*D32/100 -> 313.81903
A33: 拉塞尔 | B33: 奔驰 | C33: 99.95 | D33: =INDEX($A$2:$K$12,MATCH($B33,$A$2:$A$12,0),11) -> 312.7425 | E33: =C33*D33/100 -> 312.58613
A34: 塞恩斯 | B34: 法拉利 | C34: 99.9 | D34: =INDEX($A$2:$K$12,MATCH($B34,$A$2:$A$12,0),11) -> 312.56875 | E34: =C34*D34/100 -> 312.25618
A35: 佩雷兹 | B35: 红牛 | C35: 99.9 | D35: =INDEX($A$2:$K$12,MATCH($B35,$A$2:$A$12,0),11) -> 312.55625 | E35: =C35*D35/100 -> 312.24369
A36: 加斯利 | B36: 小红牛 | C36: 100.1 | D36: =INDEX($A$2:$K$12,MATCH($B36,$A$2:$A$12,0),11) -> 303.6625 | E36: =C36*D36/100 -> 303.96616
A37: 角田裕毅 | B37: 小红牛 | C37: 99.8 | D37: =INDEX($A$2:$K$12,MATCH($B37,$A$2:$A$12,0),11) -> 303.6625 | E37: =C37*D37/100 -> 303.05518
A38: 阿隆索 | B38: Alpine | C38: 100.5 | D38: =INDEX($A$2:$K$12,MATCH($B38,$A$2:$A$12,0),11) -> 300.8875 | E38: =C38*D38/100 -> 302.39194
A39: 维特尔 | B39: 马丁 | C39: 100.3 | D39: =INDEX($A$2:$K$12,MATCH($B39,$A$2:$A$12,0),11) -> 300.05 | E39: =C39*D39/100 -> 300.95015
A40: 奥康 | B40: Alpine | C40: 99.85 | D40: =INDEX($A$2:$K$12,MATCH($B40,$A$2:$A$12,0),11) -> 300.8875 | E40: =C40*D40/100 -> 300.43617
A41: 格罗斯让 | B41: 安德雷蒂 | C41: 100.1 | D41: =INDEX($A$2:$K$12,MATCH($B41,$A$2:$A$12,0),11) -> 299.25 | E41: =C41*D41/100 -> 299.54925
... A51: 拉提菲 | B51: 威队 | C51: 99.6 | D51: =INDEX($A$2:$K$12,MATCH($B51,$A$2:$A$12,0),11) -> 292.25 | E51: =C51*D51/100 -> 291.081
A54: 车手 | B54: 车队 | C54: DR | D54: 骰点 | E54: 增值 | F54: 结算
...

Sheet 西班牙
A1: 车队 | B1: 机械O | C1: 升级 | D1: 机械 | E1: 空动O | F1: 升级 | G1: 空动 | H1: 动力O | I1: 升级 | J1: 动力 | K1: PR | L1: 稳定性O | M1: 升级 | N1: 稳定性
A2: Alpine | B2: 93 | C2: =IF($B18=2,$I18,0) -> 0 | D2: =$B2+$C2 -> 93 | E2: 94.5 | F2: =IF($B18=1,$I18,0) -> 0 | G2: =$E2+$F2 -> 94.5 | H2: 97 | I2: =IF($B18=3,$I18,0) -> 0 | J2: =$H2+$I2 -> 97 | K2: =$D2*$B$15+$G2*$C$15+$J2*$D$15 -> 296.1625 | L2: 97.75 | M2: =IF($B18=4,$I18,0) -> 1 | N2: =$L2+$M2 -> 98.75
A3: 奔驰 | B3: 99.75 | C3: =IF($B19=2,$I19,0) -> 0 | D3: =$B3+$C3 -> 99.75 | E3: 94.9 | F3: =IF($B19=1,$I19,0) -> 0 | G3: =$E3+$F3 -> 94.9 | H3: 101 | I3: =IF($B19=3,$I19,0) -> 0 | J3: =$H3+$I3 -> 101 | K3: =$D3*$B$15+$G3*$C$15+$J3*$D$15 -> 307.9975 | L3: 97 | M3: =IF($B19=4,$I19,0) -> 0.45 | N3: =$L3+$M3 -> 97.45
A4: 阿罗 | B4: 90 | C4: =IF($B20=2,$I20,0) -> 0 | D4: =$B4+$C4 -> 90 | E4: 93.25 | F4: =IF($B20=1,$I20,0) -> 0 | G4: =$E4+$F4 -> 93.25 | H4: 99.4 | I4: =IF($B20=3,$I20,0) -> 0 | J4: =$H4+$I4 -> 99.4 | K4: =$D4*$B$15+$G4*$C$15+$J4*$D$15 -> 293.98125 | L4: 95 | M4: =IF($B20=4,$I20,0) -> 0 | N4: =$L4+$M4 -> 95
A5: 法拉利 | B5: 98.75 | C5: =IF($B21=2,$I21,0) -> 0 | D5: =$B5+$C5 -> 98.75 | E5: 97.25 | F5: =IF($B21=1,$I21,0) -> 0 | G5: =$E5+$F5 -> 97.25 | H5: 99.4 | I5: =IF($B21=3,$I21,0) -> 0 | J5: =$H5+$I5 -> 99.4 | K5: =$D5*$B$15+$G5*$C$15+$J5*$D$15 -> 307.70625 | L5: 95 | M5: =IF($B21=4,$I21,0) -> 0.75 | N5: =$L5+$M5 -> 95.75
A6: 哈斯 | B6: 88 | C6: =IF($B22=2,$I22,0) -> 0.5 | D6: =$B6+$C6 -> 88.5 | E6: 91 | F6: =IF($B22=1,$I22,0) -> 0 | G6: =$E6+$F6 -> 91 | H6: 99.4 | I6: =IF($B22=3,$I22,0) -> 0 | J6: =$H6+$I6 -> 99.4 | K6: =$D6*$B$15+$G6*$C$15+$J6*$D$15 -> 290.025 | L6: 97.5 | M6: =IF($B22=4,$I22,0) -> 0 | N6: =$L6+$M6 -> 97.5
A7: 红牛 | B7: 95 | C7: =IF($B23=2,$I23,0) -> 0.75 | D7: =$B7+$C7 -> 95.75 | E7: 100.75 | F7: =IF($B23=1,$I23,0) -> 0 | G7: =$E7+$F7 -> 100.75 | H7: 99.75 | I7: =IF($B23=3,$I23,0) -> 0 | J7: =$H7+$I7 -> 99.75 | K7: =$D7*$B$15+$G7*$C$15+$J7*$D$15 -> 308.34375 | L7: 96 | M7: =IF($B23=4,$I23,0) -> 0 | N7: =$L7+$M7 -> 96
A8: 马丁 | B8: 93 | C8: =IF($B24=2,$I24,0) -> 0 | D8: =$B8+$C8 -> 93 | E8: 90 | F8: =IF($B24=1,$I24,0) -> 1 | G8: =$E8+$F8 -> 91 | H8: 101 | I8: =IF($B24=3,$I24,0) -> 0 | J8: =$H8+$I8 -> 101 | K8: =$D8*$B$15+$G8*$C$15+$J8*$D$15 -> 296.575 | L8: 98.5 | M8: =IF($B24=4,$I24,0) -> 0 | N8: =$L8+$M8 -> 98.5
A9: 迈凯轮 | B9: 91 | C9: =IF($B25=2,$I25,0) -> 0 | D9: =$B9+$C9 -> 91 | E9: 89.5 | F9: =IF($B25=1,$I25,0) -> 1.5 | G9: =$E9+$F9 -> 91 | H9: 101 | I9: =IF($B25=3,$I25,0) -> 0 | J9: =$H9+$I9 -> 101 | K9: =$D9*$B$15+$G9*$C$15+$J9*$D$15 -> 294.375 | L9: 96.5 | M9: =IF($B25=4,$I25,0) -> 0 | N9: =$L9+$M9 -> 96.5
A10: 威队 | B10: 89.75 | C10: =IF($B26=2,$I26,0) -> 1.5 | D10: =$B10+$C10 -> 91.25 | E10: 87 | F10: =IF($B26=1,$I26,0) -> 0 | G10: =$E10+$F10 -> 87 | H10: 100 | I10: =IF($B26=3,$I26,0) -> 0 | J10: =$H10+$I10 -> 100 | K10: =$D10*$B$15+$G10*$C$15+$J10*$D$15 -> 289.55 | L10: 95 | M10: =IF($B26=4,$I26,0) -> 0 | N10: =$L10+$M10 -> 95
A11: 小红牛 | B11: 94 | C11: =IF($B27=2,$I27,0) -> 0.5 | D11: =$B11+$C11 -> 94.5 | E11: 93.5 | F11: =IF($B27=1,$I27,0) -> 0 | G11: =$E11+$F11 -> 93.5 | H11: 99.75 | I11: =IF($B27=3,$I27,0) -> 0 | J11: =$H11+$I11 -> 99.75 | K11: =$D11*$B$15+$G11*$C$15+$J11*$D$15 -> 299.5375 | L11: 96 | M11: =IF($B27=4,$I27,0) -> 0 | N11: =$L11+$M11 -> 96
A12: 安德雷蒂 | B12: 92 | C12: =IF($B28=2,$I28,0) -> 0 | D12: =$B12+$C12 -> 92 | E12: 94 | F12: =IF($B28=1,$I28,0) -> 0 | G12: =$E12+$F12 -> 94 | H12: 97 | I12: =IF($B28=3,$I28,0) -> 0 | J12: =$H12+$I12 -> 97 | K12: =$D12*$B$15+$G12*$C$15+$J12*$D$15 -> 294.55 | L12: 97 | M12: 0 | N12: =$L12+$M12 -> 97
B14: C(M) | C14: C(A) | D14: C(P)
A15: 西班牙 | B15: 1.1 | C15: 1.025 | D15: 1
A17: 车队 | B17: 升级内容骰点 | C17: 升级大项目 | D17: 升级小项骰 | E17: 升级小项 | F17: 升级点数骰 | G17: 升级点数 | H17: 倍率 | I17: 最终 | K17: 升级内容 | N17: 空力 | O17: 机械 | P17: PU | Q17: 稳定性
A18: Alpine | B18: 4 | C18: =LOOKUP($B18,$K$18:$K$21,$L$18:$L$21) -> 稳定性 | D18: 5 | E18: =INDEX($N$18:$Q$27,$D18,$B18) -> 稳定性 | F18: 4 | G18: =LOOKUP($F18,$R$18:$R$27,$S$18:$S$27) -> 0.5 | H18: 2 | I18: =$G18*$H18 -> 1 | K18: 1 | L18: 空力 | M18: 1 | N18: 尾翼 | O18: 底板加固 | P18: ERS | Q18: 稳定性 | R18: 1 | S18: 0
A19: 奔驰 | B19: 4 | C19: =LOOKUP($B19,$K$18:$K$21,$L$18:$L$21) -> 稳定性 | D19: 10 | E19: =INDEX($N$18:$Q$27,$D19,$B19) -> 稳定性 | F19: 5 | G19: =LOOKUP($F19,$R$18:$R$27,$S$18:$S$27) -> 0.5 | H19: 0.9 | I19: =$G19*$H19 -> 0.45 | J19: 埃利奥特开坑 | K19: 2 | L19: 机械 | M19: 2 | N19: 前翼 | O19: 减重 | P19: 冷却 | Q19: 稳定性 | R19: 2 | S19: 0.25
A20: 阿罗 | B20: 1 | C20: =LOOKUP($B20,$K$18:$K$21,$L$18:$L$21) -> 空力 | D20: 9 | E20: =INDEX($N$18:$Q$27,$D20,$B20) -> 侧箱 | F20: 1 | G20: =LOOKUP($F20,$R$18:$R$27,$S$18:$S$27) -> 0 | H20: 2 | I20: =$G20*$H20 -> 0 | K20: 3 | L20: PU | M20: 3 | N20: 扩散器 | O20: 悬挂 | P20: ICE | Q20: 稳定性 | R20: 3 | S20: 0.25
A21: 法拉利 | B21: 4 | C21: =LOOKUP($B21,$K$18:$K$21,$L$18:$L$21) -> 稳定性 | D21: 4 | E21: =INDEX($N$18:$Q$27,$D21,$B21) -> 稳定性 | F21: 8 | G21: =LOOKUP($F21,$R$18:$R$27,$S$18:$S$27) -> 0.75 | H21: 1 | I21: =$G21*$H21 -> 0.75 | K21: 4 | L21: 稳定性 | M21: 4 | N21: 侧箱 | O21: 底板加固 | P21: ERS | Q21: 稳定性 | R21: 4 | S21: 0.5
A22: 哈斯 | B22: 2 | C22: =LOOKUP($B22,$K$18:$K$21,$L$18:$L$21) -> 机械 | D22: 7 | E22: =INDEX($N$18:$Q$27,$D22,$B22) -> 底板加固 | F22: 2 | G22: =LOOKUP($F22,$R$18:$R$27,$S$18:$S$27) -> 0.25 | H22: 2 | I22: =$G22*$H22 -> 0.5 | M22: 5 | N22: 底板 | O22: 减重 | P22: 冷却 | Q22: 稳定性 | R22: 5 | S22: 0.5
A23: 红牛 | B23: 2 | C23: =LOOKUP($B23,$K$18:$K$21,$L$18:$L$21) -> 机械 | D23: 2 | E23: =INDEX($N$18:$Q$27,$D23,$B23) -> 减重 | F23: 9 | G23: =LOOKUP($F23,$R$18:$R$27,$S$18:$S$27) -> 0.75 | H23: 1 | I23: =$G23*$H23 -> 0.75 | M23: 6 | N23: 尾翼 | O23: 悬挂 | P23: ICE | Q23: 稳定性 | R23: 6 | S23: 0.5
A24: 马丁 | B24: 1 | C24: =LOOKUP($B24,$K$18:$K$21,$L$18:$L$21) -> 空力 | D24: 8 | E24: =INDEX($N$18:$Q$27,$D24,$B24) -> 扩散器 | F24: 7 | G24: =LOOKUP($F24,$R$18:$R$27,$S$18:$S$27) -> 0.5 | H24: 2 | I24: =$G24*$H24 -> 1 | M24: 7 | N24: 前翼 | O24: 底板加固 | P24: ERS | Q24: 稳定性 | R24: 7 | S24: 0.5
A25: 迈凯轮 | B25: 1 | C25: =LOOKUP($B25,$K$18:$K$21,$L$18:$L$21) -> 空力 | D25: 7 | E25: =INDEX($N$18:$Q$27,$D25,$B25) -> 前翼 | F25: 9 | G25: =LOOKUP($F25,$R$18:$R$27,$S$18:$S$27) -> 0.75 | H25: 2 | I25: =$G25*$H25 -> 1.5 | M25: 8 | N25: 扩散器 | O25: 减重 | P25: 冷却 | Q25: 稳定性 | R25: 8 | S25: 0.75
A26: 威队 | B26: 2 | C26: =LOOKUP($B26,$K$18:$K$21,$L$18:$L$21) -> 机械 | D26: 2 | E26: =INDEX($N$18:$Q$27,$D26,$B26) -> 减重 | F26: 9 | G26: =LOOKUP($F26,$R$18:$R$27,$S$18:$S$27) -> 0.75 | H26: 2 | I26: =$G26*$H26 -> 1.5 | M26: 9 | N26: 侧箱 | O26: 悬挂 | P26: ICE | Q26: 稳定性 | R26: 9 | S26: 0.75
A27: 小红牛 | B27: 2 | C27: =LOOKUP($B27,$K$18:$K$21,$L$18:$L$21) -> 机械 | D27: 8 | E27: =INDEX($N$18:$Q$27,$D27,$B27) -> 减重 | F27: 2 | G27: =LOOKUP($F27,$R$18:$R$27,$S$18:$S$27) -> 0.25 | H27: 2 | I27: =$G27*$H27 -> 0.5 | M27: 10 | N27: 底板 | O27: Reroll | P27: 起Token | Q27: 稳定性 | R27: 10 | S27: 1
A29: 车手 | B29: 车手 | C29: 车队 | D29: DR | E29: PR | F29: RO
A30: VER | B30: 维斯塔潘 | C30: 红牛 | D30: 100.5 | E30: =INDEX($A$2:$K$12,MATCH($C30,$A$2:$A$12,0),11) -> 308.34375 | F30: =D30*E30/100 -> 309.88547
A31: HAM | B31: 汉密尔顿 | C31: 奔驰 | D31: 100.4 | E31: =INDEX($A$2:$K$12,MATCH($C31,$A$2:$A$12,0),11) -> 307.9975 | F31: =D31*E31/100 -> 309.22949
A32: LEC | B32: 勒克莱尔 | C32: 法拉利 | D32: 100.4 | E32: =INDEX($A$2:$K$12,MATCH($C32,$A$2:$A$12,0),11) -> 307.70625 | F32: =D32*E32/100 -> 308.93707
A33: PER | B33: 佩雷兹 | C33: 红牛 | D33: 99.9 | E33: =INDEX($A$2:$K$12,MATCH($C33,$A$2:$A$12,0),11) -> 308.34375 | F33: =D33*E33/100 -> 308.03541
A34: RUS | B34: 拉塞尔 | C34: 奔驰 | D34: 99.95 | E34: =INDEX($A$2:$K$12,MATCH($C34,$A$2:$A$12,0),11) -> 307.9975 | F34: =D34*E34/100 -> 307.8435
A35: SAI | B35: 塞恩斯 | C35: 法拉利 | D35: 99.9 | E35: =INDEX($A$2:$K$12,MATCH($C35,$A$2:$A$12,0),11) -> 307.70625 | F35: =D35*E35/100 -> 307.39854
A36: GAS | B36: 加斯利 | C36: 小红牛 | D36: 100.1 | E36: =INDEX($A$2:$K$12,MATCH($C36,$A$2:$A$12,0),11) -> 299.5375 | F36: =D36*E36/100 -> 299.83704
A37: TSU | B37: 角田裕毅 | C37: 小红牛 | D37: 99.8 | E37: =INDEX($A$2:$K$12,MATCH($C37,$A$2:$A$12,0),11) -> 299.5375 | F37: =D37*E37/100 -> 298.93842
A38: ALO | B38: 阿隆索 | C38: Alpine | D38: 100.5 | E38: =INDEX($A$2:$K$12,MATCH($C38,$A$2:$A$12,0),11) -> 296.1625 | F38: =D38*E38/100 -> 297.64331
A39: VET | B39: 维特尔 | C39: 马丁 | D39: 100.3 | E39: =INDEX($A$2:$K$12,MATCH($C39,$A$2:$A$12,0),11) -> 296.575 | F39: =D39*E39/100 -> 297.46472
A40: OCO | B40: 奥康 | C40: Alpine | D40: 99.85 | E40: =INDEX($A$2:$K$12,MATCH($C40,$A$2:$A$12,0),11) -> 296.1625 | F40: =D40*E40/100 -> 295.71826
A41: STR | B41: 斯特罗尔 | C41: 马丁 | D41: 99.65 | E41: =INDEX($A$2:$K$12,MATCH($C41,$A$2:$A$12,0),11) -> 296.575 | F41: =D41*E41/100 -> 295.53699
B42: 格罗斯让 | C42: 安德雷蒂 | D42: 100.1 | E42: =INDEX($A$2:$K$12,MATCH($C42,$A$2:$A$12,0),11) -> 294.55 | F42: =D42*E42/100 -> 294.84455
A43: NOR | B43: 诺里斯 | C43: 迈凯轮 | D43: 100.1 | E43: =INDEX($A$2:$K$12,MATCH($C43,$A$2:$A$12,0),11) -> 294.375 | F43: =D43*E43/100 -> 294.66938
...

Sheet 积分榜
A1: 排名 | B1: 车号 | C1: 车手 | D1: 车队 | E1: 总分 | F1: 巴林 | G1: 沙特 | H1: 澳大利亚 | I1: 伊冲 | J1: 伊莫拉 | K1: 迈阿密 | L1: 西班牙 | M1: 摩纳哥 | N1: 阿塞拜疆 | O1: 加拿大 | P1: 英国 | Q1: 奥冲 | R1: 奥地利 | S1: 法国 | T1: 匈牙利 | U1: 比利时 | V1: 荷兰 | W1: 蒙扎 | X1: 中国 | Y1: 新加坡 | Z1: 日本 | AA1: COTA | AB1: 墨西哥 | AC1: 巴冲 | AD1: 巴西 | AE1: 阿布扎比
A2: =RANK(E2,$E$2:$E$25) -> 1 | B2: 16 | C2: 勒克莱尔 | D2: 法拉利 | E2: =SUM(F2:AE2) -> 129 | F2: 26 | G2: 25 | H2: 26 | I2: 8 | J2: 25 | K2: 19
A3: =RANK(E3,$E$2:$E$25) -> 2 | B3: 1 | C3: 维斯塔潘 | D3: 红牛 | E3: =SUM(F3:AE3) -> 100 | F3: 18 | G3: 19 | H3: 12 | I3: 7 | J3: 19 | K3: 25
A4: =RANK(E4,$E$2:$E$25) -> 3 | B4: 55 | C4: 塞恩斯 | D4: 法拉利 | E4: =SUM(F4:AE4) -> 66 | F4: 0 | G4: 15 | H4: 18 | I4: 6 | J4: 12 | K4: 15
A5: =RANK(E5,$E$2:$E$25) -> 4 | B5: 63 | C5: 拉塞尔 | D5: 奔驰 | E5: =SUM(F5:AE5) -> 47 | F5: 8 | G5: 8 | H5: 8 | I5: 3 | J5: 8 | K5: 12
A6: =RANK(E6,$E$2:$E$25) -> 5 | B6: 11 | C6: 佩雷兹 | D6: 红牛 | E6: =SUM(F6:AE6) -> 42 | F6: 0 | G6: 12 | H6: 10 | I6: 5 | J6: 15 | K6: 0
A7: =RANK(E7,$E$2:$E$25) -> 6 | B7: 44 | C7: 汉密尔顿 | D7: 奔驰 | E7: =SUM(F7:AE7) -> 39 | F7: 0 | G7: 10 | H7: 15 | I7: 4 | J7: 10 | K7: 0
A8: =RANK(E8,$E$2:$E$25) -> 7 | B8: 14 | C8: 阿隆索 | D8: Alpine | E8: =SUM(F8:AE8) -> 33 | F8: 15 | G8: 2 | H8: 2 | I8: 0 | J8: 6 | K8: 8
A9: =RANK(E9,$E$2:$E$25) -> 8 | B9: 10 | C9: 加斯利 | D9: 小红牛 | E9: =SUM(F9:AE9) -> 30 | F9: 12 | G9: 6 | H9: 0 | I9: 2 | J9: 0 | K9: 10
A10: =RANK(E10,$E$2:$E$25) -> 9 | B10: 22 | C10: 角田裕毅 | D10: 小红牛 | E10: =SUM(F10:AE10) -> 12 | F10: 1 | G10: 0 | H10: 4 | I10: 1 | J10: 0 | K10: 6
A11: =RANK(E11,$E$2:$E$25) -> 10 | B11: 27 | C11: 霍肯伯格 | D11: 马丁 | E11: =SUM(F11:AE11) -> 10 | F11: 10
A12: =RANK(E12,$E$2:$E$25) -> 11 | B12: 31 | C12: 奥康 | D12: Alpine | E12: =SUM(F12:AE12) -> 9 | F12: 0 | G12: 1 | H12: 0 | I12: 0 | J12: 4 | K12: 4
A13: =RANK(E13,$E$2:$E$25) -> 12 | B13: 18 | C13: 斯特罗尔 | D13: 马丁 | E13: =SUM(F13:AE13) -> 8 | F13: 6 | G13: 0 | H13: 0 | I13: 0 | J13: 1 | K13: 1
A14: =RANK(E14,$E$2:$E$25) -> 12 | B14: 5 | C14: 维特尔 | D14: 马丁 | E14: =SUM(F14:AE14) -> 8 | G14: 4 | H14: 0 | I14: 0 | J14: 2 | K14: 2
A15: =RANK(E15,$E$2:$E$25) -> 14 | B15: 24 | C15: 周冠宇 | D15: 阿罗 | E15: =SUM(F15:AE15) -> 6 | F15: 0 | G15: 0 | H15: 6 | I15: 0 | J15: 0 | K15: 0
A16: =RANK(E16,$E$2:$E$25) -> 15 | B16: 4 | C16: 诺里斯 | D16: 迈凯轮 | E16: =SUM(F16:AE16) -> 4 | F16: 4 | G16: 0 | H16: 0 | I16: 0 | J16: 0 | K16: 0
A17: =RANK(E17,$E$2:$E$25) -> 16 | B17: 47 | C17: 米克 | D17: 哈斯 | E17: =SUM(F17:AE17) -> 2 | F17: 2 | G17: 0 | H17: 0 | I17: 0 | J17: 0 | K17: 0
A18: =RANK(E18,$E$2:$E$25) -> 17 | B18: 77 | C18: 博塔斯 | D18: 阿罗 | E18: =SUM(F18:AE18) -> 1 | F18: 0 | G18: 0 | H18: 1 | I18: 0 | J18: 0 | K18: 0
A19: =RANK(E19,$E$2:$E$25) -> 18 | B19: 3 | C19: 里卡多 | D19: 迈凯轮 | E19: =SUM(F19:AE19) -> 0 | F19: 0 | G19: 0 | H19: 0
A20: =RANK(E20,$E$2:$E$25) -> 18 | B20: 23 | C20: 阿尔本 | D20: 威廉姆斯 | E20: =SUM(F20:AE20) -> 0 | F20: 0 | G20: 0 | H20: 0 | I20: 0 | J20: 0 | K20: 0
A21: =RANK(E21,$E$2:$E$25) -> 18 | B21: 6 | C21: 拉提菲 | D21: 威廉姆斯 | E21: =SUM(F21:AE21) -> 0 | F21: 0 | G21: 0 | H21: 0 | I21: 0 | J21: 0 | K21: 0
A22: =RANK(E22,$E$2:$E$25) -> 18 | B22: 20 | C22: 马格努森 | D22: 哈斯 | E22: =SUM(F22:AE22) -> 0 | F22: 0 | G22: 0 | H22: 0 | I22: 0 | J22: 0 | K22: 0
A23: =RANK(E23,$E$2:$E$25) -> 18 | B23: 81 | C23: 皮亚斯特里 | D23: 迈凯轮 | E23: =SUM(F23:AE23) -> 0 | I23: 0 | J23: 0 | K23: 0
A24: =RANK(E24,$E$2:$E$25) -> 18 | B24: 8 | C24: 格罗斯让 | D24: 安德雷蒂 | E24: =SUM(F24:AE24) -> 0 | K24: 0
A25: =RANK(E25,$E$2:$E$25) -> 18 | B25: 39 | C25: 施瓦茨曼 | D25: 安德雷蒂 | E25: =SUM(F25:AE25) -> 0 | K25: 0
A27: 排名 | B27: 车队 | C27: 总分 | D27: 巴林 | E27: 沙特 | F27: 澳大利亚 | G27: 伊冲 | H27: 伊莫拉 | I27: 迈阿密 | J27: 西班牙 | K27: 摩纳哥 | L27: 阿塞拜疆 | M27: 加拿大 | N27: 英国 | O27: 奥冲 | P27: 奥地利 | Q27: 法国 | R27: 匈牙利 | S27: 比利时 | T27: 荷兰 | U27: 蒙扎 | V27: 中国 | W27: 新加坡 | X27: 日本 | Y27: COTA | Z27: 墨西哥 | AA27: 巴冲 | AB27: 巴西 | AC27: 阿布扎比
A28: =RANK(C28,$C$28:$C$38) -> 1 | B28: 法拉利 | C28: =SUM(E2,E4) -> 195 | D28: =IF(AND(F2="",F4=""),"",SUM(F2,F4)) -> 26 | E28: =IF(AND(G2="",G4=""),"",SUM(G2,G4)) -> 40 | F28: =IF(AND(H2="",H4=""),"",SUM(H2,H4)) -> 44 | G28: =IF(AND(I2="",I4=""),"",SUM(I2,I4)) -> 14 | H28: =IF(AND(J2="",J4=""),"",SUM(J2,J4)) -> 37 | I28: =IF(AND(K2="",K4=""),"",SUM(K2,K4)) -> 34 | J28: =IF(AND(L2="",L4=""),"",SUM(L2,L4)) | K28: =IF(AND(M2="",M4=""),"",SUM(M2,M4)) | ... AC28: =IF(AND(AE2="",AE4=""),"",SUM(AE2,AE4))
A29: =RANK(C29,$C$28:$C$38) -> 2 | B29: 红牛 | C29: =SUM(E3,E6) -> 142 | D29: =IF(AND(F3="",F6=""),"",SUM(F3,F6)) -> 18 | E29: =IF(AND(G3="",G6=""),"",SUM(G3,G6)) -> 31 | F29: =IF(AND(H3="",H6=""),"",SUM(H3,H6)) -> 22 | G29: =IF(AND(I3="",I6=""),"",SUM(I3,I6)) -> 12 | H29: =IF(AND(J3="",J6=""),"",SUM(J3,J6)) -> 34 | I29: =IF(AND(K3="",K6=""),"",SUM(K3,K6)) -> 25 | J29: =IF(AND(L3="",L6=""),"",SUM(L3,L6)) | K29: =IF(AND(M3="",M6=""),"",SUM(M3,M6)) | ... AC29: =IF(AND(AE3="",AE6=""),"",SUM(AE3,AE6))
A30: =RANK(C30,$C$28:$C$38) -> 3 | B30: 奔驰 | C30: =SUM(E5,E7) -> 86 | D30: =IF(AND(F5="",F7=""),"",SUM(F5,F7)) -> 8 | E30: =IF(AND(G5="",G7=""),"",SUM(G5,G7)) -> 18 | F30: =IF(AND(H5="",H7=""),"",SUM(H5,H7)) -> 23 | G30: =IF(AND(I5="",I7=""),"",SUM(I5,I7)) -> 7 | H30: =IF(AND(J5="",J7=""),"",SUM(J5,J7)) -> 18 | I30: =IF(AND(K5="",K7=""),"",SUM(K5,K7)) -> 12 | J30: =IF(AND(L5="",L7=""),"",SUM(L5,L7)) | K30: =IF(AND(M5="",M7=""),"",SUM(M5,M7)) | ... AC30: =IF(AND(AE5="",AE7=""),"",SUM(AE5,AE7))
A31: =RANK(C31,$C$28:$C$38) -> 4 | B31: Alpine | C31: =SUM(E8,E12) -> 42 | D31: =IF(AND(F8="",F12=""),"",SUM(F8,F12)) -> 15 | E31: =IF(AND(G8="",G12=""),"",SUM(G8,G12)) -> 3 | F31: =IF(AND(H8="",H12=""),"",SUM(H8,H12)) -> 2 | G31: =IF(AND(I8="",I12=""),"",SUM(I8,I12)) -> 0 | H31: =IF(AND(J8="",J12=""),"",SUM(J8,J12)) -> 10 | I31: =IF(AND(K8="",K12=""),"",SUM(K8,K12)) -> 12 | J31: =IF(AND(L8="",L12=""),"",SUM(L8,L12)) | K31: =IF(AND(M8="",M12=""),"",SUM(M8,M12)) | ... AC31: =IF(AND(AE8="",AE12=""),"",SUM(AE8,AE12))
A32: =RANK(C32,$C$28:$C$38) -> 4 | B32: 小红牛 | C32: =SUM(D32:AB32) -> 42 | D32: =IF(AND(F9="",F10=""),"",SUM(F9,F10)) -> 13 | E32: =IF(AND(G9="",G10=""),"",SUM(G9,G10)) -> 6 | F32: =IF(AND(H9="",H10=""),"",SUM(H9,H10)) -> 4 | G32: =IF(AND(I9="",I10=""),"",SUM(I9,I10)) -> 3 | H32: =IF(AND(J9="",J10=""),"",SUM(J9,J10)) -> 0 | I32: =IF(AND(K9="",K10=""),"",SUM(K9,K10)) -> 16 | J32: =IF(AND(L9="",L10=""),"",SUM(L9,L10)) | K32: =IF(AND(M9="",M10=""),"",SUM(M9,M10)) | ... AC32: =IF(AND(AE9="",AE10=""),"",SUM(AE9,AE10))
A33: =RANK(C33,$C$28:$C$38) -> 6 | B33: 马丁 | C33: =SUM(E11,E13,E14) -> 26 | D33: =IF(AND(F11="",F13="",F14=""),"",SUM(F11,F13,F14)) -> 16 | E33: =IF(AND(G11="",G13="",G14=""),"",SUM(G11,G13,G14)) -> 4 | F33: =IF(AND(H11="",H13="",H14=""),"",SUM(H11,H13,H14)) -> 0 | G33: =IF(AND(I11="",I13="",I14=""),"",SUM(I11,I13,I14)) -> 0 | H33: =IF(AND(J11="",J13="",J14=""),"",SUM(J11,J13,J14)) -> 3 | I33: =IF(AND(K11="",K13="",K14=""),"",SUM(K11,K13,K14)) -> 3 | J33: =IF(AND(L11="",L13="",L14=""),"",SUM(L11,L13,L14)) | K33: =IF(AND(M11="",M13="",M14=""),"",SUM(M11,M13,M14)) | ... AC33: =IF(AND(AE11="",AE13="",AE14=""),"",SUM(AE11,AE13,AE14))
A34: =RANK(C34,$C$28:$C$38) -> 7 | B34: 阿罗 | C34: =SUM(E15,E18) -> 7 | D34: =IF(AND(F15="",F18=""),"",SUM(F15,F18)) -> 0 | E34: =IF(AND(G15="",G18=""),"",SUM(G15,G18)) -> 0 | F34: =IF(AND(H15="",H18=""),"",SUM(H15,H18)) -> 7 | G34: =IF(AND(I15="",I18=""),"",SUM(I15,I18)) -> 0 | H34: =IF(AND(J15="",J18=""),"",SUM(J15,J18)) -> 0 | I34: =IF(AND(K15="",K18=""),"",SUM(K15,K18)) -> 0 | J34: =IF(AND(L15="",L18=""),"",SUM(L15,L18)) | K34: =IF(AND(M15="",M18=""),"",SUM(M15,M18)) | ... AC34: =IF(AND(AE15="",AE18=""),"",SUM(AE15,AE18))
A35: =RANK(C35,$C$28:$C$38) -> 8 | B35: 迈凯轮 | C35: =SUM(E16,E19,E23) -> 4 | D35: =IF(AND(F16="",F19=""),"",SUM(F16,F19)) -> 4 | E35: =IF(AND(G16="",G19=""),"",SUM(G16,G19)) -> 0 | F35: =IF(AND(H16="",H19=""),"",SUM(H16,H19)) -> 0 | G35: =IF(AND(I16="",I19=""),"",SUM(I16,I19)) -> 0 | H35: =IF(AND(J16="",J19=""),"",SUM(J16,J19)) -> 0 | I35: =IF(AND(K16="",K19=""),"",SUM(K16,K19)) -> 0 | J35: =IF(AND(L16="",L19=""),"",SUM(L16,L19)) | K35: =IF(AND(M16="",M19=""),"",SUM(M16,M19)) | ... AC35: =IF(AND(AE16="",AE19=""),"",SUM(AE16,AE19))
A36: =RANK(C36,$C$28:$C$38) -> 9 | B36: 哈斯 | C36: =SUM(E17,E22) -> 2 | D36: =IF(AND(F17="",F22=""),"",SUM(F17,F22)) -> 2 | E36: =IF(AND(G17="",G22=""),"",SUM(G17,G22)) -> 0 | F36: =IF(AND(H17="",H22=""),"",SUM(H17,H22)) -> 0 | G36: =IF(AND(I17="",I22=""),"",SUM(I17,I22)) -> 0 | H36: =IF(AND(J17="",J22=""),"",SUM(J17,J22)) -> 0 | I36: =IF(AND(K17="",K22=""),"",SUM(K17,K22)) -> 0 | J36: =IF(AND(L17="",L22=""),"",SUM(L17,L22)) | K36: =IF(AND(M17="",M22=""),"",SUM(M17,M22)) | ... AC36: =IF(AND(AE17="",AE22=""),"",SUM(AE17,AE22))
A37: =RANK(C37,$C$28:$C$38) -> 10 | B37: 威廉姆斯 | C37: =SUM(E20,E21) -> 0 | D37: =IF(AND(F20="",F21=""),"",SUM(F20,F21)) -> 0 | E37: =IF(AND(G20="",G21=""),"",SUM(G20,G21)) -> 0 | F37: =IF(AND(H20="",H21=""),"",SUM(H20,H21)) -> 0 | G37: =IF(AND(I20="",I21=""),"",SUM(I20,I21)) -> 0 | H37: =IF(AND(J20="",J21=""),"",SUM(J20,J21)) -> 0 | I37: =IF(AND(K20="",K21=""),"",SUM(K20,K21)) -> 0 | J37: =IF(AND(L20="",L21=""),"",SUM(L20,L21)) | K37: =IF(AND(M20="",M21=""),"",SUM(M20,M21)) | ... AC37: =IF(AND(AE20="",AE21=""),"",SUM(AE20,AE21))
A38: =RANK(C38,$C$28:$C$38) -> 10 | B38: 安德雷蒂 | C38: =SUM(E24,E25) -> 0 | D38: =IF(AND(F24="",F25=""),"",SUM(F24,F25)) | E38: =IF(AND(G24="",G25=""),"",SUM(G24,G25)) | F38: =IF(AND(H24="",H25=""),"",SUM(H24,H25)) | G38: =IF(AND(I24="",I25=""),"",SUM(I24,I25)) | H38: =IF(AND(J24="",J25=""),"",SUM(J24,J25)) | I38: =IF(AND(K24="",K25=""),"",SUM(K24,K25)) -> 0 | J38: =IF(AND(L24="",L25=""),"",SUM(L24,L25)) | K38: =IF(AND(M24="",M25=""),"",SUM(M24,M25)) | ... AC38: =IF(AND(AE24="",AE25=""),"",SUM(AE24,AE25))
C42: End | D42: 车号 | E42: 车手 | F42: 积分
C43: 1 | D43: 16 | E43: 勒克莱尔 | F43: 25
C44: 2 | D44: 1 | E44: 维斯塔潘 | F44: 19
...

Sheet WDC
A1: Ranking | B1: Driver | AD1: Points
A2: =RANK(AD2,$AD$2:$AD$22,0) -> 1 | C2: Charles Leclerc | D2: =IF(积分榜!F2="","",积分榜!F2) -> 26 | E2: =IF(积分榜!G2="","",积分榜!G2) -> 25 | F2: =IF(积分榜!H2="","",积分榜!H2) -> 26 | G2: =IF(积分榜!I2="","",积分榜!I2) -> 8 | H2: =IF(积分榜!J2="","",积分榜!J2) -> 25 | I2: =IF(积分榜!K2="","",积分榜!K2) -> 19 | J2: =IF(积分榜!L2="","",积分榜!L2) | K2: =IF(积分榜!M2="","",积分榜!M2) | ... AC2: =IF(积分榜!AE2="","",积分榜!AE2) | AD2: =SUM(D2:AC2) -> 129
A3: =RANK(AD3,$AD$2:$AD$22,0) -> 2 | C3: Max Verstappen | D3: =IF(积分榜!F3="","",积分榜!F3) -> 18 | E3: =IF(积分榜!G3="","",积分榜!G3) -> 19 | F3: =IF(积分榜!H3="","",积分榜!H3) -> 12 | G3: =IF(积分榜!I3="","",积分榜!I3) -> 7 | H3: =IF(积分榜!J3="","",积分榜!J3) -> 19 | I3: =IF(积分榜!K3="","",积分榜!K3) -> 25 | J3: =IF(积分榜!L3="","",积分榜!L3) | K3: =IF(积分榜!M3="","",积分榜!M3) | ... AC3: =IF(积分榜!AE3="","",积分榜!AE3) | AD3: =SUM(D3:AC3) -> 100
A4: =RANK(AD4,$AD$2:$AD$22,0) -> 3 | C4: Carlos Sainz Jr. | D4: Ret | E4: =IF(积分榜!G4="","",积分榜!G4) -> 15 | F4: =IF(积分榜!H4="","",积分榜!H4) -> 18 | G4: =IF(积分榜!I4="","",积分榜!I4) -> 6 | H4: =IF(积分榜!J4="","",积分榜!J4) -> 12 | I4: =IF(积分榜!K4="","",积分榜!K4) -> 15 | J4: =IF(积分榜!L4="","",积分榜!L4) | K4: =IF(积分榜!M4="","",积分榜!M4) | L4: =IF(积分榜!N4="","",积分榜!N4) | ... AC4: =IF(积分榜!AE4="","",积分榜!AE4) | AD4: =SUM(D4:AC4) -> 66
A5: =RANK(AD5,$AD$2:$AD$22,0) -> 4 | C5: George Russell | D5: =IF(积分榜!F5="","",积分榜!F5) -> 8 | E5: =IF(积分榜!G5="","",积分榜!G5) -> 8 | F5: =IF(积分榜!H5="","",积分榜!H5) -> 8 | G5: =IF(积分榜!I5="","",积分榜!I5) -> 3 | H5: =IF(积分榜!J5="","",积分榜!J5) -> 8 | I5: =IF(积分榜!K5="","",积分榜!K5) -> 12 | J5: =IF(积分榜!L5="","",积分榜!L5) | K5: =IF(积分榜!M5="","",积分榜!M5) | ... AC5: =IF(积分榜!AE5="","",积分榜!AE5) | AD5: =SUM(D5:AC5) -> 47
A6: =RANK(AD6,$AD$2:$AD$22,0) -> 5 | C6: Sergio Pérez | D6: Ret | E6: =IF(积分榜!G6="","",积分榜!G6) -> 12 | F6: =IF(积分榜!H6="","",积分榜!H6) -> 10 | G6: =IF(积分榜!I6="","",积分榜!I6) -> 5 | H6: =IF(积分榜!J6="","",积分榜!J6) -> 15 | I6: Ret | J6: =IF(积分榜!L6="","",积分榜!L6) | K6: =IF(积分榜!M6="","",积分榜!M6) | L6: =IF(积分榜!N6="","",积分榜!N6) | M6: =IF(积分榜!O6="","",积分榜!O6) | N6: =IF(积分榜!P6="","",积分榜!P6) | O6: =IF(积分榜!Q6="","",积分榜!Q6) | P6: =IF(积分榜!R6="","",积分榜!R6) | Q6: =IF(积分榜!S6="","",积分榜!S6) | ... AC6: =IF(积分榜!AE6="","",积分榜!AE6) | AD6: =SUM(D6:AC6) -> 42
A7: =RANK(AD7,$AD$2:$AD$22,0) -> 6 | C7: Lewis Hamilton | D7: Ret | E7: =IF(积分榜!G7="","",积分榜!G7) -> 10 | F7: =IF(积分榜!H7="","",积分榜!H7) -> 15 | G7: =IF(积分榜!I7="","",积分榜!I7) -> 4 | H7: =IF(积分榜!J7="","",积分榜!J7) -> 10 | I7: Ret | J7: =IF(积分榜!L7="","",积分榜!L7) | K7: =IF(积分榜!M7="","",积分榜!M7) | L7: =IF(积分榜!N7="","",积分榜!N7) | M7: =IF(积分榜!O7="","",积分榜!O7) | N7: =IF(积分榜!P7="","",积分榜!P7) | O7: =IF(积分榜!Q7="","",积分榜!Q7) | P7: =IF(积分榜!R7="","",积分榜!R7) | Q7: =IF(积分榜!S7="","",积分榜!S7) | ... AC7: =IF(积分榜!AE7="","",积分榜!AE7) | AD7: =SUM(D7:AC7) -> 39
A8: =RANK(AD8,$AD$2:$AD$22,0) -> 7 | C8: Fernando Alonso | D8: =IF(积分榜!F8="","",积分榜!F8) -> 15 | E8: =IF(积分榜!G8="","",积分榜!G8) -> 2 | F8: =IF(积分榜!H8="","",积分榜!H8) -> 2 | G8: =IF(积分榜!I8="","",积分榜!I8) -> 0 | H8: =IF(积分榜!J8="","",积分榜!J8) -> 6 | I8: =IF(积分榜!K8="","",积分榜!K8) -> 8 | J8: =IF(积分榜!L8="","",积分榜!L8) | K8: =IF(积分榜!M8="","",积分榜!M8) | ... AC8: =IF(积分榜!AE8="","",积分榜!AE8) | AD8: =SUM(D8:AC8) -> 33
A9: =RANK(AD9,$AD$2:$AD$22,0) -> 8 | C9: Pierre Gasly | D9: =IF(积分榜!F9="","",积分榜!F9) -> 12 | E9: =IF(积分榜!G9="","",积分榜!G9) -> 6 | F9: Ret | G9: =IF(积分榜!I9="","",积分榜!I9) -> 2 | H9: =IF(积分榜!J9="","",积分榜!J9) -> 0 | I9: =IF(积分榜!K9="","",积分榜!K9) -> 10 | J9: =IF(积分榜!L9="","",积分榜!L9) | K9: =IF(积分榜!M9="","",积分榜!M9) | L9: =IF(积分榜!N9="","",积分榜!N9) | M9: =IF(积分榜!O9="","",积分榜!O9) | N9: =IF(积分榜!P9="","",积分榜!P9) | ... AC9: =IF(积分榜!AE9="","",积分榜!AE9) | AD9: =SUM(D9:AC9) -> 30
A10: =RANK(AD10,$AD$2:$AD$22,0) -> 9 | C10: Yuki Tsunoda | D10: =IF(积分榜!F10="","",积分榜!F10) -> 1 | E10: Ret | F10: =IF(积分榜!H10="","",积分榜!H10) -> 4 | G10: =IF(积分榜!I10="","",积分榜!I10) -> 1 | H10: =IF(积分榜!J10="","",积分榜!J10) -> 0 | I10: =IF(积分榜!K10="","",积分榜!K10) -> 6 | J10: =IF(积分榜!L10="","",积分榜!L10) | K10: =IF(积分榜!M10="","",积分榜!M10) | L10: =IF(积分榜!N10="","",积分榜!N10) | M10: =IF(积分榜!O10="","",积分榜!O10) | ... AC10: =IF(积分榜!AE10="","",积分榜!AE10) | AD10: =SUM(D10:AC10) -> 12
A11: =RANK(AD11,$AD$2:$AD$22,0) -> 10 | C11: Nico Hülkenberg | D11: =IF(积分榜!F11="","",积分榜!F11) -> 10 | E11: =IF(积分榜!G11="","",积分榜!G11) | F11: =IF(积分榜!H11="","",积分榜!H11) | G11: =IF(积分榜!I11="","",积分榜!I11) | H11: =IF(积分榜!J11="","",积分榜!J11) | I11: =IF(积分榜!K11="","",积分榜!K11) | J11: =IF(积分榜!L11="","",积分榜!L11) | K11: =IF(积分榜!M11="","",积分榜!M11) | ... AC11: =IF(积分榜!AE11="","",积分榜!AE11) | AD11: =SUM(D11:AC11) -> 10
A12: =RANK(AD12,$AD$2:$AD$22,0) -> 11 | C12: Esteban Ocon | D12: =IF(积分榜!F12="","",积分榜!F12) -> 0 | E12: =IF(积分榜!G12="","",积分榜!G12) -> 1 | F12: =IF(积分榜!H12="","",积分榜!H12) -> 0 | G12: =IF(积分榜!I12="","",积分榜!I12) -> 0 | H12: =IF(积分榜!J12="","",积分榜!J12) -> 4 | I12: =IF(积分榜!K12="","",积分榜!K12) -> 4 | J12: =IF(积分榜!L12="","",积分榜!L12) | K12: =IF(积分榜!M12="","",积分榜!M12) | ... AC12: =IF(积分榜!AE12="","",积分榜!AE12) | AD12: =SUM(D12:AC12) -> 9
A13: =RANK(AD13,$AD$2:$AD$22,0) -> 12 | C13: Lance Stroll | D13: =IF(积分榜!F13="","",积分榜!F13) -> 6 | E13: =IF(积分榜!G13="","",积分榜!G13) -> 0 | F13: Ret | G13: =IF(积分榜!I13="","",积分榜!I13) -> 0 | H13: =IF(积分榜!J13="","",积分榜!J13) -> 1 | I13: =IF(积分榜!K13="","",积分榜!K13) -> 1 | J13: =IF(积分榜!L13="","",积分榜!L13) | K13: =IF(积分榜!M13="","",积分榜!M13) | L13: =IF(积分榜!N13="","",积分榜!N13) | M13: =IF(积分榜!O13="","",积分榜!O13) | N13: =IF(积分榜!P13="","",积分榜!P13) | ... AC13: =IF(积分榜!AE13="","",积分榜!AE13) | AD13: =SUM(D13:AC13) -> 8
A14: =RANK(AD14,$AD$2:$AD$22,0) -> 12 | C14: Sebastian Vettel | D14: =IF(积分榜!F14="","",积分榜!F14) | E14: =IF(积分榜!G14="","",积分榜!G14) -> 4 | F14: Ret | G14: =IF(积分榜!I14="","",积分榜!I14) -> 0 | H14: =IF(积分榜!J14="","",积分榜!J14) -> 2 | I14: =IF(积分榜!K14="","",积分榜!K14) -> 2 | J14: =IF(积分榜!L14="","",积分榜!L14) | K14: =IF(积分榜!M14="","",积分榜!M14) | L14: =IF(积分榜!N14="","",积分榜!N14) | M14: =IF(积分榜!O14="","",积分榜!O14) | N14: =IF(积分榜!P14="","",积分榜!P14) | ... AC14: =IF(积分榜!AE14="","",积分榜!AE14) | AD14: =SUM(D14:AC14) -> 8
A15: =RANK(AD15,$AD$2:$AD$22,0) -> 14 | C15: Zhou Guanyu | D15: =IF(积分榜!F15="","",积分榜!F15) -> 0 | E15: =IF(积分榜!G15="","",积分榜!G15) -> 0 | F15: =IF(积分榜!H15="","",积分榜!H15) -> 6 | G15: =IF(积分榜!I15="","",积分榜!I15) -> 0 | H15: =IF(积分榜!J15="","",积分榜!J15) -> 0 | I15: Ret | J15: =IF(积分榜!L15="","",积分榜!L15) | K15: =IF(积分榜!M15="","",积分榜!M15) | L15: =IF(积分榜!N15="","",积分榜!N15) | M15: =IF(积分榜!O15="","",积分榜!O15) | N15: =IF(积分榜!P15="","",积分榜!P15) | O15: =IF(积分榜!Q15="","",积分榜!Q15) | P15: =IF(积分榜!R15="","",积分榜!R15) | Q15: =IF(积分榜!S15="","",积分榜!S15) | ... AC15: =IF(积分榜!AE15="","",积分榜!AE15) | AD15: =SUM(D15:AC15) -> 6
A16: =RANK(AD16,$AD$2:$AD$22,0) -> 15 | C16: Lando Norris | D16: =IF(积分榜!F16="","",积分榜!F16) -> 4 | E16: =IF(积分榜!G16="","",积分榜!G16) -> 0 | F16: =IF(积分榜!H16="","",积分榜!H16) -> 0 | G16: =IF(积分榜!I16="","",积分榜!I16) -> 0 | H16: =IF(积分榜!J16="","",积分榜!J16) -> 0 | I16: Ret | J16: =IF(积分榜!L16="","",积分榜!L16) | K16: =IF(积分榜!M16="","",积分榜!M16) | L16: =IF(积分榜!N16="","",积分榜!N16) | M16: =IF(积分榜!O16="","",积分榜!O16) | N16: =IF(积分榜!P16="","",积分榜!P16) | O16: =IF(积分榜!Q16="","",积分榜!Q16) | P16: =IF(积分榜!R16="","",积分榜!R16) | Q16: =IF(积分榜!S16="","",积分榜!S16) | ... AC16: =IF(积分榜!AE16="","",积分榜!AE16) | AD16: =SUM(D16:AC16) -> 4
